ERROR 2017-02-14 09:42:15,587 base 19756 4359663616 Internal Server Error: /admin/metastore/rbacuserroleaccess/
Traceback (most recent call last):
  File "/Users/abhishek.ranjan/virtualenvs/metastore/lib/python2.7/site-packages/django/core/handlers/base.py", line 111, in get_response
    response = wrapped_callback(request, *callback_args, **callback_kwargs)
  File "/Users/abhishek.ranjan/virtualenvs/metastore/lib/python2.7/site-packages/django/contrib/admin/options.py", line 583, in wrapper
    return self.admin_site.admin_view(view)(*args, **kwargs)
  File "/Users/abhishek.ranjan/virtualenvs/metastore/lib/python2.7/site-packages/django/utils/decorators.py", line 105, in _wrapped_view
    response = view_func(request, *args, **kwargs)
  File "/Users/abhishek.ranjan/virtualenvs/metastore/lib/python2.7/site-packages/django/views/decorators/cache.py", line 52, in _wrapped_view_func
    response = view_func(request, *args, **kwargs)
  File "/Users/abhishek.ranjan/virtualenvs/metastore/lib/python2.7/site-packages/django/contrib/admin/sites.py", line 206, in inner
    return view(request, *args, **kwargs)
  File "/Users/abhishek.ranjan/virtualenvs/metastore/lib/python2.7/site-packages/django/utils/decorators.py", line 29, in _wrapper
    return bound_func(*args, **kwargs)
  File "/Users/abhishek.ranjan/virtualenvs/metastore/lib/python2.7/site-packages/django/utils/decorators.py", line 105, in _wrapped_view
    response = view_func(request, *args, **kwargs)
  File "/Users/abhishek.ranjan/virtualenvs/metastore/lib/python2.7/site-packages/django/utils/decorators.py", line 25, in bound_func
    return func.__get__(self, type(self))(*args2, **kwargs2)
  File "/Users/abhishek.ranjan/virtualenvs/metastore/lib/python2.7/site-packages/django/contrib/admin/options.py", line 1485, in changelist_view
    self.list_max_show_all, self.list_editable, self)
  File "/Users/abhishek.ranjan/virtualenvs/metastore/lib/python2.7/site-packages/django/contrib/admin/views/main.py", line 109, in __init__
    self.queryset = self.get_queryset(request)
  File "/Users/abhishek.ranjan/virtualenvs/metastore/lib/python2.7/site-packages/django/contrib/admin/views/main.py", line 359, in get_queryset
    filters_use_distinct) = self.get_filters(request)
  File "/Users/abhishek.ranjan/virtualenvs/metastore/lib/python2.7/site-packages/django/contrib/admin/views/main.py", line 175, in get_filters
    self.model, self.model_admin, field_path=field_path)
  File "/Users/abhishek.ranjan/virtualenvs/metastore/lib/python2.7/site-packages/django/contrib/admin/filters.py", line 158, in create
    model, model_admin, field_path=field_path)
  File "/Users/abhishek.ranjan/virtualenvs/metastore/lib/python2.7/site-packages/django/contrib/admin/filters.py", line 172, in __init__
    self.lookup_choices = field.get_choices(include_blank=False)
  File "/Users/abhishek.ranjan/virtualenvs/metastore/lib/python2.7/site-packages/django/db/models/fields/__init__.py", line 750, in get_choices
    self.get_limit_choices_to())]
  File "/Users/abhishek.ranjan/virtualenvs/metastore/lib/python2.7/site-packages/django/db/models/query.py", line 141, in __iter__
    self._fetch_all()
  File "/Users/abhishek.ranjan/virtualenvs/metastore/lib/python2.7/site-packages/django/db/models/query.py", line 966, in _fetch_all
    self._result_cache = list(self.iterator())
  File "/Users/abhishek.ranjan/virtualenvs/metastore/lib/python2.7/site-packages/django/db/models/query.py", line 265, in iterator
    for row in compiler.results_iter():
  File "/Users/abhishek.ranjan/virtualenvs/metastore/lib/python2.7/site-packages/django/db/models/sql/compiler.py", line 700, in results_iter
    for rows in self.execute_sql(MULTI):
  File "/Users/abhishek.ranjan/virtualenvs/metastore/lib/python2.7/site-packages/django/db/models/sql/compiler.py", line 786, in execute_sql
    cursor.execute(sql, params)
  File "/Users/abhishek.ranjan/virtualenvs/metastore/lib/python2.7/site-packages/django/db/backends/utils.py", line 81, in execute
    return super(CursorDebugWrapper, self).execute(sql, params)
  File "/Users/abhishek.ranjan/virtualenvs/metastore/lib/python2.7/site-packages/django/db/backends/utils.py", line 65, in execute
    return self.cursor.execute(sql, params)
  File "/Users/abhishek.ranjan/virtualenvs/metastore/lib/python2.7/site-packages/django/db/utils.py", line 94, in __exit__
    six.reraise(dj_exc_type, dj_exc_value, traceback)
  File "/Users/abhishek.ranjan/virtualenvs/metastore/lib/python2.7/site-packages/django/db/backends/utils.py", line 65, in execute
    return self.cursor.execute(sql, params)
  File "/Users/abhishek.ranjan/virtualenvs/metastore/lib/python2.7/site-packages/django/db/backends/mysql/base.py", line 129, in execute
    return self.cursor.execute(query, args)
  File "/Users/abhishek.ranjan/virtualenvs/metastore/lib/python2.7/site-packages/MySQLdb/cursors.py", line 205, in execute
    self.errorhandler(self, exc, value)
  File "/Users/abhishek.ranjan/virtualenvs/metastore/lib/python2.7/site-packages/MySQLdb/connections.py", line 36, in defaulterrorhandler
    raise errorclass, errorvalue
OperationalError: (1054, "Unknown column 'rbac_entity_attribute.is_dimension' in 'field list'")
ERROR 2017-02-14 09:43:01,491 base 22210 4478205952 Internal Server Error: /admin/metastore/rbacuserroleaccess/
Traceback (most recent call last):
  File "/Users/abhishek.ranjan/virtualenvs/metastore/lib/python2.7/site-packages/django/core/handlers/base.py", line 111, in get_response
    response = wrapped_callback(request, *callback_args, **callback_kwargs)
  File "/Users/abhishek.ranjan/virtualenvs/metastore/lib/python2.7/site-packages/django/contrib/admin/options.py", line 583, in wrapper
    return self.admin_site.admin_view(view)(*args, **kwargs)
  File "/Users/abhishek.ranjan/virtualenvs/metastore/lib/python2.7/site-packages/django/utils/decorators.py", line 105, in _wrapped_view
    response = view_func(request, *args, **kwargs)
  File "/Users/abhishek.ranjan/virtualenvs/metastore/lib/python2.7/site-packages/django/views/decorators/cache.py", line 52, in _wrapped_view_func
    response = view_func(request, *args, **kwargs)
  File "/Users/abhishek.ranjan/virtualenvs/metastore/lib/python2.7/site-packages/django/contrib/admin/sites.py", line 206, in inner
    return view(request, *args, **kwargs)
  File "/Users/abhishek.ranjan/virtualenvs/metastore/lib/python2.7/site-packages/django/utils/decorators.py", line 29, in _wrapper
    return bound_func(*args, **kwargs)
  File "/Users/abhishek.ranjan/virtualenvs/metastore/lib/python2.7/site-packages/django/utils/decorators.py", line 105, in _wrapped_view
    response = view_func(request, *args, **kwargs)
  File "/Users/abhishek.ranjan/virtualenvs/metastore/lib/python2.7/site-packages/django/utils/decorators.py", line 25, in bound_func
    return func.__get__(self, type(self))(*args2, **kwargs2)
  File "/Users/abhishek.ranjan/virtualenvs/metastore/lib/python2.7/site-packages/django/contrib/admin/options.py", line 1485, in changelist_view
    self.list_max_show_all, self.list_editable, self)
  File "/Users/abhishek.ranjan/virtualenvs/metastore/lib/python2.7/site-packages/django/contrib/admin/views/main.py", line 109, in __init__
    self.queryset = self.get_queryset(request)
  File "/Users/abhishek.ranjan/virtualenvs/metastore/lib/python2.7/site-packages/django/contrib/admin/views/main.py", line 359, in get_queryset
    filters_use_distinct) = self.get_filters(request)
  File "/Users/abhishek.ranjan/virtualenvs/metastore/lib/python2.7/site-packages/django/contrib/admin/views/main.py", line 175, in get_filters
    self.model, self.model_admin, field_path=field_path)
  File "/Users/abhishek.ranjan/virtualenvs/metastore/lib/python2.7/site-packages/django/contrib/admin/filters.py", line 158, in create
    model, model_admin, field_path=field_path)
  File "/Users/abhishek.ranjan/virtualenvs/metastore/lib/python2.7/site-packages/django/contrib/admin/filters.py", line 172, in __init__
    self.lookup_choices = field.get_choices(include_blank=False)
  File "/Users/abhishek.ranjan/virtualenvs/metastore/lib/python2.7/site-packages/django/db/models/fields/__init__.py", line 750, in get_choices
    self.get_limit_choices_to())]
  File "/Users/abhishek.ranjan/virtualenvs/metastore/lib/python2.7/site-packages/django/db/models/query.py", line 141, in __iter__
    self._fetch_all()
  File "/Users/abhishek.ranjan/virtualenvs/metastore/lib/python2.7/site-packages/django/db/models/query.py", line 966, in _fetch_all
    self._result_cache = list(self.iterator())
  File "/Users/abhishek.ranjan/virtualenvs/metastore/lib/python2.7/site-packages/django/db/models/query.py", line 265, in iterator
    for row in compiler.results_iter():
  File "/Users/abhishek.ranjan/virtualenvs/metastore/lib/python2.7/site-packages/django/db/models/sql/compiler.py", line 700, in results_iter
    for rows in self.execute_sql(MULTI):
  File "/Users/abhishek.ranjan/virtualenvs/metastore/lib/python2.7/site-packages/django/db/models/sql/compiler.py", line 786, in execute_sql
    cursor.execute(sql, params)
  File "/Users/abhishek.ranjan/virtualenvs/metastore/lib/python2.7/site-packages/django/db/backends/utils.py", line 81, in execute
    return super(CursorDebugWrapper, self).execute(sql, params)
  File "/Users/abhishek.ranjan/virtualenvs/metastore/lib/python2.7/site-packages/django/db/backends/utils.py", line 65, in execute
    return self.cursor.execute(sql, params)
  File "/Users/abhishek.ranjan/virtualenvs/metastore/lib/python2.7/site-packages/django/db/utils.py", line 94, in __exit__
    six.reraise(dj_exc_type, dj_exc_value, traceback)
  File "/Users/abhishek.ranjan/virtualenvs/metastore/lib/python2.7/site-packages/django/db/backends/utils.py", line 65, in execute
    return self.cursor.execute(sql, params)
  File "/Users/abhishek.ranjan/virtualenvs/metastore/lib/python2.7/site-packages/django/db/backends/mysql/base.py", line 129, in execute
    return self.cursor.execute(query, args)
  File "/Users/abhishek.ranjan/virtualenvs/metastore/lib/python2.7/site-packages/MySQLdb/cursors.py", line 205, in execute
    self.errorhandler(self, exc, value)
  File "/Users/abhishek.ranjan/virtualenvs/metastore/lib/python2.7/site-packages/MySQLdb/connections.py", line 36, in defaulterrorhandler
    raise errorclass, errorvalue
OperationalError: (1054, "Unknown column 'rbac_entity_attribute.is_pivoted_measure' in 'field list'")
ERROR 2017-02-14 10:45:55,257 base 22268 4469346304 Internal Server Error: /admin/metastore/jobtable/517/
Traceback (most recent call last):
  File "/Users/abhishek.ranjan/virtualenvs/metastore/lib/python2.7/site-packages/django/core/handlers/base.py", line 111, in get_response
    response = wrapped_callback(request, *callback_args, **callback_kwargs)
  File "/Users/abhishek.ranjan/virtualenvs/metastore/lib/python2.7/site-packages/django/contrib/admin/options.py", line 583, in wrapper
    return self.admin_site.admin_view(view)(*args, **kwargs)
  File "/Users/abhishek.ranjan/virtualenvs/metastore/lib/python2.7/site-packages/django/utils/decorators.py", line 105, in _wrapped_view
    response = view_func(request, *args, **kwargs)
  File "/Users/abhishek.ranjan/virtualenvs/metastore/lib/python2.7/site-packages/django/views/decorators/cache.py", line 52, in _wrapped_view_func
    response = view_func(request, *args, **kwargs)
  File "/Users/abhishek.ranjan/virtualenvs/metastore/lib/python2.7/site-packages/django/contrib/admin/sites.py", line 195, in inner
    if not self.has_permission(request):
  File "/Users/abhishek.ranjan/virtualenvs/metastore/lib/python2.7/site-packages/django/contrib/admin/sites.py", line 152, in has_permission
    return request.user.is_active and request.user.is_staff
  File "/Users/abhishek.ranjan/virtualenvs/metastore/lib/python2.7/site-packages/django/utils/functional.py", line 224, in inner
    self._setup()
  File "/Users/abhishek.ranjan/virtualenvs/metastore/lib/python2.7/site-packages/django/utils/functional.py", line 357, in _setup
    self._wrapped = self._setupfunc()
  File "/Users/abhishek.ranjan/virtualenvs/metastore/lib/python2.7/site-packages/django/contrib/auth/middleware.py", line 22, in <lambda>
    request.user = SimpleLazyObject(lambda: get_user(request))
  File "/Users/abhishek.ranjan/virtualenvs/metastore/lib/python2.7/site-packages/django/contrib/auth/middleware.py", line 10, in get_user
    request._cached_user = auth.get_user(request)
  File "/Users/abhishek.ranjan/virtualenvs/metastore/lib/python2.7/site-packages/django/contrib/auth/__init__.py", line 152, in get_user
    user_id = request.session[SESSION_KEY]
  File "/Users/abhishek.ranjan/virtualenvs/metastore/lib/python2.7/site-packages/django/contrib/sessions/backends/base.py", line 49, in __getitem__
    return self._session[key]
  File "/Users/abhishek.ranjan/virtualenvs/metastore/lib/python2.7/site-packages/django/contrib/sessions/backends/base.py", line 175, in _get_session
    self._session_cache = self.load()
  File "/Users/abhishek.ranjan/virtualenvs/metastore/lib/python2.7/site-packages/django/contrib/sessions/backends/db.py", line 21, in load
    expire_date__gt=timezone.now()
  File "/Users/abhishek.ranjan/virtualenvs/metastore/lib/python2.7/site-packages/django/db/models/manager.py", line 92, in manager_method
    return getattr(self.get_queryset(), name)(*args, **kwargs)
  File "/Users/abhishek.ranjan/virtualenvs/metastore/lib/python2.7/site-packages/django/db/models/query.py", line 351, in get
    num = len(clone)
  File "/Users/abhishek.ranjan/virtualenvs/metastore/lib/python2.7/site-packages/django/db/models/query.py", line 122, in __len__
    self._fetch_all()
  File "/Users/abhishek.ranjan/virtualenvs/metastore/lib/python2.7/site-packages/django/db/models/query.py", line 966, in _fetch_all
    self._result_cache = list(self.iterator())
  File "/Users/abhishek.ranjan/virtualenvs/metastore/lib/python2.7/site-packages/django/db/models/query.py", line 265, in iterator
    for row in compiler.results_iter():
  File "/Users/abhishek.ranjan/virtualenvs/metastore/lib/python2.7/site-packages/django/db/models/sql/compiler.py", line 700, in results_iter
    for rows in self.execute_sql(MULTI):
  File "/Users/abhishek.ranjan/virtualenvs/metastore/lib/python2.7/site-packages/django/db/models/sql/compiler.py", line 784, in execute_sql
    cursor = self.connection.cursor()
  File "/Users/abhishek.ranjan/virtualenvs/metastore/lib/python2.7/site-packages/django/db/backends/__init__.py", line 165, in cursor
    cursor = self.make_debug_cursor(self._cursor())
  File "/Users/abhishek.ranjan/virtualenvs/metastore/lib/python2.7/site-packages/django/db/backends/__init__.py", line 138, in _cursor
    self.ensure_connection()
  File "/Users/abhishek.ranjan/virtualenvs/metastore/lib/python2.7/site-packages/django/db/backends/__init__.py", line 133, in ensure_connection
    self.connect()
  File "/Users/abhishek.ranjan/virtualenvs/metastore/lib/python2.7/site-packages/django/db/utils.py", line 94, in __exit__
    six.reraise(dj_exc_type, dj_exc_value, traceback)
  File "/Users/abhishek.ranjan/virtualenvs/metastore/lib/python2.7/site-packages/django/db/backends/__init__.py", line 133, in ensure_connection
    self.connect()
  File "/Users/abhishek.ranjan/virtualenvs/metastore/lib/python2.7/site-packages/django/db/backends/__init__.py", line 122, in connect
    self.connection = self.get_new_connection(conn_params)
  File "/Users/abhishek.ranjan/virtualenvs/metastore/lib/python2.7/site-packages/django/db/backends/mysql/base.py", line 472, in get_new_connection
    conn = Database.connect(**conn_params)
  File "/Users/abhishek.ranjan/virtualenvs/metastore/lib/python2.7/site-packages/MySQLdb/__init__.py", line 81, in Connect
    return Connection(*args, **kwargs)
  File "/Users/abhishek.ranjan/virtualenvs/metastore/lib/python2.7/site-packages/MySQLdb/connections.py", line 193, in __init__
    super(Connection, self).__init__(*args, **kwargs2)
OperationalError: (2003, "Can't connect to MySQL server on '127.0.0.1' (61)")
ERROR 2017-02-14 10:46:00,389 base 22268 4469346304 Internal Server Error: /admin/metastore/jobtable/
Traceback (most recent call last):
  File "/Users/abhishek.ranjan/virtualenvs/metastore/lib/python2.7/site-packages/django/core/handlers/base.py", line 111, in get_response
    response = wrapped_callback(request, *callback_args, **callback_kwargs)
  File "/Users/abhishek.ranjan/virtualenvs/metastore/lib/python2.7/site-packages/django/contrib/admin/options.py", line 583, in wrapper
    return self.admin_site.admin_view(view)(*args, **kwargs)
  File "/Users/abhishek.ranjan/virtualenvs/metastore/lib/python2.7/site-packages/django/utils/decorators.py", line 105, in _wrapped_view
    response = view_func(request, *args, **kwargs)
  File "/Users/abhishek.ranjan/virtualenvs/metastore/lib/python2.7/site-packages/django/views/decorators/cache.py", line 52, in _wrapped_view_func
    response = view_func(request, *args, **kwargs)
  File "/Users/abhishek.ranjan/virtualenvs/metastore/lib/python2.7/site-packages/django/contrib/admin/sites.py", line 195, in inner
    if not self.has_permission(request):
  File "/Users/abhishek.ranjan/virtualenvs/metastore/lib/python2.7/site-packages/django/contrib/admin/sites.py", line 152, in has_permission
    return request.user.is_active and request.user.is_staff
  File "/Users/abhishek.ranjan/virtualenvs/metastore/lib/python2.7/site-packages/django/utils/functional.py", line 224, in inner
    self._setup()
  File "/Users/abhishek.ranjan/virtualenvs/metastore/lib/python2.7/site-packages/django/utils/functional.py", line 357, in _setup
    self._wrapped = self._setupfunc()
  File "/Users/abhishek.ranjan/virtualenvs/metastore/lib/python2.7/site-packages/django/contrib/auth/middleware.py", line 22, in <lambda>
    request.user = SimpleLazyObject(lambda: get_user(request))
  File "/Users/abhishek.ranjan/virtualenvs/metastore/lib/python2.7/site-packages/django/contrib/auth/middleware.py", line 10, in get_user
    request._cached_user = auth.get_user(request)
  File "/Users/abhishek.ranjan/virtualenvs/metastore/lib/python2.7/site-packages/django/contrib/auth/__init__.py", line 152, in get_user
    user_id = request.session[SESSION_KEY]
  File "/Users/abhishek.ranjan/virtualenvs/metastore/lib/python2.7/site-packages/django/contrib/sessions/backends/base.py", line 49, in __getitem__
    return self._session[key]
  File "/Users/abhishek.ranjan/virtualenvs/metastore/lib/python2.7/site-packages/django/contrib/sessions/backends/base.py", line 175, in _get_session
    self._session_cache = self.load()
  File "/Users/abhishek.ranjan/virtualenvs/metastore/lib/python2.7/site-packages/django/contrib/sessions/backends/db.py", line 21, in load
    expire_date__gt=timezone.now()
  File "/Users/abhishek.ranjan/virtualenvs/metastore/lib/python2.7/site-packages/django/db/models/manager.py", line 92, in manager_method
    return getattr(self.get_queryset(), name)(*args, **kwargs)
  File "/Users/abhishek.ranjan/virtualenvs/metastore/lib/python2.7/site-packages/django/db/models/query.py", line 351, in get
    num = len(clone)
  File "/Users/abhishek.ranjan/virtualenvs/metastore/lib/python2.7/site-packages/django/db/models/query.py", line 122, in __len__
    self._fetch_all()
  File "/Users/abhishek.ranjan/virtualenvs/metastore/lib/python2.7/site-packages/django/db/models/query.py", line 966, in _fetch_all
    self._result_cache = list(self.iterator())
  File "/Users/abhishek.ranjan/virtualenvs/metastore/lib/python2.7/site-packages/django/db/models/query.py", line 265, in iterator
    for row in compiler.results_iter():
  File "/Users/abhishek.ranjan/virtualenvs/metastore/lib/python2.7/site-packages/django/db/models/sql/compiler.py", line 700, in results_iter
    for rows in self.execute_sql(MULTI):
  File "/Users/abhishek.ranjan/virtualenvs/metastore/lib/python2.7/site-packages/django/db/models/sql/compiler.py", line 784, in execute_sql
    cursor = self.connection.cursor()
  File "/Users/abhishek.ranjan/virtualenvs/metastore/lib/python2.7/site-packages/django/db/backends/__init__.py", line 165, in cursor
    cursor = self.make_debug_cursor(self._cursor())
  File "/Users/abhishek.ranjan/virtualenvs/metastore/lib/python2.7/site-packages/django/db/backends/__init__.py", line 138, in _cursor
    self.ensure_connection()
  File "/Users/abhishek.ranjan/virtualenvs/metastore/lib/python2.7/site-packages/django/db/backends/__init__.py", line 133, in ensure_connection
    self.connect()
  File "/Users/abhishek.ranjan/virtualenvs/metastore/lib/python2.7/site-packages/django/db/utils.py", line 94, in __exit__
    six.reraise(dj_exc_type, dj_exc_value, traceback)
  File "/Users/abhishek.ranjan/virtualenvs/metastore/lib/python2.7/site-packages/django/db/backends/__init__.py", line 133, in ensure_connection
    self.connect()
  File "/Users/abhishek.ranjan/virtualenvs/metastore/lib/python2.7/site-packages/django/db/backends/__init__.py", line 122, in connect
    self.connection = self.get_new_connection(conn_params)
  File "/Users/abhishek.ranjan/virtualenvs/metastore/lib/python2.7/site-packages/django/db/backends/mysql/base.py", line 472, in get_new_connection
    conn = Database.connect(**conn_params)
  File "/Users/abhishek.ranjan/virtualenvs/metastore/lib/python2.7/site-packages/MySQLdb/__init__.py", line 81, in Connect
    return Connection(*args, **kwargs)
  File "/Users/abhishek.ranjan/virtualenvs/metastore/lib/python2.7/site-packages/MySQLdb/connections.py", line 193, in __init__
    super(Connection, self).__init__(*args, **kwargs2)
OperationalError: (2003, "Can't connect to MySQL server on '127.0.0.1' (61)")
ERROR 2017-02-14 15:56:44,150 base 38268 4341288960 Internal Server Error: /
Traceback (most recent call last):
  File "/Users/abhishek.ranjan/virtualenvs/metastore/lib/python2.7/site-packages/django/core/handlers/base.py", line 98, in get_response
    resolver_match = resolver.resolve(request.path_info)
  File "/Users/abhishek.ranjan/virtualenvs/metastore/lib/python2.7/site-packages/django/core/urlresolvers.py", line 343, in resolve
    for pattern in self.url_patterns:
  File "/Users/abhishek.ranjan/virtualenvs/metastore/lib/python2.7/site-packages/django/core/urlresolvers.py", line 372, in url_patterns
    patterns = getattr(self.urlconf_module, "urlpatterns", self.urlconf_module)
  File "/Users/abhishek.ranjan/virtualenvs/metastore/lib/python2.7/site-packages/django/core/urlresolvers.py", line 366, in urlconf_module
    self._urlconf_module = import_module(self.urlconf_name)
  File "/System/Library/Frameworks/Python.framework/Versions/2.7/lib/python2.7/importlib/__init__.py", line 37, in import_module
    __import__(name)
  File "/Users/abhishek.ranjan/lols/metastore/metastore/urls.py", line 4, in <module>
    from metastore import views
  File "/Users/abhishek.ranjan/lols/metastore/metastore/views.py", line 5, in <module>
    from metastore.api.core import compare_reversion
ImportError: No module named core
ERROR 2017-02-14 15:56:44,537 base 38268 4341288960 Internal Server Error: /favicon.ico
Traceback (most recent call last):
  File "/Users/abhishek.ranjan/virtualenvs/metastore/lib/python2.7/site-packages/django/core/handlers/base.py", line 87, in get_response
    response = middleware_method(request)
  File "/Users/abhishek.ranjan/virtualenvs/metastore/lib/python2.7/site-packages/django/middleware/common.py", line 72, in process_request
    if (not urlresolvers.is_valid_path(request.path_info, urlconf) and
  File "/Users/abhishek.ranjan/virtualenvs/metastore/lib/python2.7/site-packages/django/core/urlresolvers.py", line 619, in is_valid_path
    resolve(path, urlconf)
  File "/Users/abhishek.ranjan/virtualenvs/metastore/lib/python2.7/site-packages/django/core/urlresolvers.py", line 494, in resolve
    return get_resolver(urlconf).resolve(path)
  File "/Users/abhishek.ranjan/virtualenvs/metastore/lib/python2.7/site-packages/django/core/urlresolvers.py", line 343, in resolve
    for pattern in self.url_patterns:
  File "/Users/abhishek.ranjan/virtualenvs/metastore/lib/python2.7/site-packages/django/core/urlresolvers.py", line 372, in url_patterns
    patterns = getattr(self.urlconf_module, "urlpatterns", self.urlconf_module)
  File "/Users/abhishek.ranjan/virtualenvs/metastore/lib/python2.7/site-packages/django/core/urlresolvers.py", line 366, in urlconf_module
    self._urlconf_module = import_module(self.urlconf_name)
  File "/System/Library/Frameworks/Python.framework/Versions/2.7/lib/python2.7/importlib/__init__.py", line 37, in import_module
    __import__(name)
  File "/Users/abhishek.ranjan/lols/metastore/metastore/urls.py", line 4, in <module>
    from metastore import views
  File "/Users/abhishek.ranjan/lols/metastore/metastore/views.py", line 5, in <module>
    from metastore.api.core import compare_reversion
ImportError: No module named core
ERROR 2017-02-14 15:57:22,747 base 38268 4341288960 Internal Server Error: /
Traceback (most recent call last):
  File "/Users/abhishek.ranjan/virtualenvs/metastore/lib/python2.7/site-packages/django/core/handlers/base.py", line 98, in get_response
    resolver_match = resolver.resolve(request.path_info)
  File "/Users/abhishek.ranjan/virtualenvs/metastore/lib/python2.7/site-packages/django/core/urlresolvers.py", line 343, in resolve
    for pattern in self.url_patterns:
  File "/Users/abhishek.ranjan/virtualenvs/metastore/lib/python2.7/site-packages/django/core/urlresolvers.py", line 372, in url_patterns
    patterns = getattr(self.urlconf_module, "urlpatterns", self.urlconf_module)
  File "/Users/abhishek.ranjan/virtualenvs/metastore/lib/python2.7/site-packages/django/core/urlresolvers.py", line 366, in urlconf_module
    self._urlconf_module = import_module(self.urlconf_name)
  File "/System/Library/Frameworks/Python.framework/Versions/2.7/lib/python2.7/importlib/__init__.py", line 37, in import_module
    __import__(name)
  File "/Users/abhishek.ranjan/lols/metastore/metastore/urls.py", line 6, in <module>
    from metastore.api.resources import resources
  File "/Users/abhishek.ranjan/lols/metastore/metastore/api/resources/resources.py", line 22, in <module>
    from metastore.api.core import utils as core_utils
ImportError: No module named core
ERROR 2017-02-14 15:57:22,990 base 38268 4341288960 Internal Server Error: /favicon.ico
Traceback (most recent call last):
  File "/Users/abhishek.ranjan/virtualenvs/metastore/lib/python2.7/site-packages/django/core/handlers/base.py", line 87, in get_response
    response = middleware_method(request)
  File "/Users/abhishek.ranjan/virtualenvs/metastore/lib/python2.7/site-packages/django/middleware/common.py", line 72, in process_request
    if (not urlresolvers.is_valid_path(request.path_info, urlconf) and
  File "/Users/abhishek.ranjan/virtualenvs/metastore/lib/python2.7/site-packages/django/core/urlresolvers.py", line 619, in is_valid_path
    resolve(path, urlconf)
  File "/Users/abhishek.ranjan/virtualenvs/metastore/lib/python2.7/site-packages/django/core/urlresolvers.py", line 494, in resolve
    return get_resolver(urlconf).resolve(path)
  File "/Users/abhishek.ranjan/virtualenvs/metastore/lib/python2.7/site-packages/django/core/urlresolvers.py", line 343, in resolve
    for pattern in self.url_patterns:
  File "/Users/abhishek.ranjan/virtualenvs/metastore/lib/python2.7/site-packages/django/core/urlresolvers.py", line 372, in url_patterns
    patterns = getattr(self.urlconf_module, "urlpatterns", self.urlconf_module)
  File "/Users/abhishek.ranjan/virtualenvs/metastore/lib/python2.7/site-packages/django/core/urlresolvers.py", line 366, in urlconf_module
    self._urlconf_module = import_module(self.urlconf_name)
  File "/System/Library/Frameworks/Python.framework/Versions/2.7/lib/python2.7/importlib/__init__.py", line 37, in import_module
    __import__(name)
  File "/Users/abhishek.ranjan/lols/metastore/metastore/urls.py", line 6, in <module>
    from metastore.api.resources import resources
  File "/Users/abhishek.ranjan/lols/metastore/metastore/api/resources/resources.py", line 22, in <module>
    from metastore.api.core import utils as core_utils
ImportError: No module named core
ERROR 2017-02-14 15:57:24,223 base 38268 4341288960 Internal Server Error: /
Traceback (most recent call last):
  File "/Users/abhishek.ranjan/virtualenvs/metastore/lib/python2.7/site-packages/django/core/handlers/base.py", line 98, in get_response
    resolver_match = resolver.resolve(request.path_info)
  File "/Users/abhishek.ranjan/virtualenvs/metastore/lib/python2.7/site-packages/django/core/urlresolvers.py", line 343, in resolve
    for pattern in self.url_patterns:
  File "/Users/abhishek.ranjan/virtualenvs/metastore/lib/python2.7/site-packages/django/core/urlresolvers.py", line 372, in url_patterns
    patterns = getattr(self.urlconf_module, "urlpatterns", self.urlconf_module)
  File "/Users/abhishek.ranjan/virtualenvs/metastore/lib/python2.7/site-packages/django/core/urlresolvers.py", line 366, in urlconf_module
    self._urlconf_module = import_module(self.urlconf_name)
  File "/System/Library/Frameworks/Python.framework/Versions/2.7/lib/python2.7/importlib/__init__.py", line 37, in import_module
    __import__(name)
  File "/Users/abhishek.ranjan/lols/metastore/metastore/urls.py", line 6, in <module>
    from metastore.api.resources import resources
  File "/Users/abhishek.ranjan/lols/metastore/metastore/api/resources/resources.py", line 22, in <module>
    from metastore.api.core import utils as core_utils
ImportError: No module named core
ERROR 2017-02-14 15:57:24,451 base 38268 4341288960 Internal Server Error: /favicon.ico
Traceback (most recent call last):
  File "/Users/abhishek.ranjan/virtualenvs/metastore/lib/python2.7/site-packages/django/core/handlers/base.py", line 87, in get_response
    response = middleware_method(request)
  File "/Users/abhishek.ranjan/virtualenvs/metastore/lib/python2.7/site-packages/django/middleware/common.py", line 72, in process_request
    if (not urlresolvers.is_valid_path(request.path_info, urlconf) and
  File "/Users/abhishek.ranjan/virtualenvs/metastore/lib/python2.7/site-packages/django/core/urlresolvers.py", line 619, in is_valid_path
    resolve(path, urlconf)
  File "/Users/abhishek.ranjan/virtualenvs/metastore/lib/python2.7/site-packages/django/core/urlresolvers.py", line 494, in resolve
    return get_resolver(urlconf).resolve(path)
  File "/Users/abhishek.ranjan/virtualenvs/metastore/lib/python2.7/site-packages/django/core/urlresolvers.py", line 343, in resolve
    for pattern in self.url_patterns:
  File "/Users/abhishek.ranjan/virtualenvs/metastore/lib/python2.7/site-packages/django/core/urlresolvers.py", line 372, in url_patterns
    patterns = getattr(self.urlconf_module, "urlpatterns", self.urlconf_module)
  File "/Users/abhishek.ranjan/virtualenvs/metastore/lib/python2.7/site-packages/django/core/urlresolvers.py", line 366, in urlconf_module
    self._urlconf_module = import_module(self.urlconf_name)
  File "/System/Library/Frameworks/Python.framework/Versions/2.7/lib/python2.7/importlib/__init__.py", line 37, in import_module
    __import__(name)
  File "/Users/abhishek.ranjan/lols/metastore/metastore/urls.py", line 6, in <module>
    from metastore.api.resources import resources
  File "/Users/abhishek.ranjan/lols/metastore/metastore/api/resources/resources.py", line 22, in <module>
    from metastore.api.core import utils as core_utils
ImportError: No module named core
ERROR 2017-02-14 15:58:03,315 base 38268 4341288960 Internal Server Error: /
Traceback (most recent call last):
  File "/Users/abhishek.ranjan/virtualenvs/metastore/lib/python2.7/site-packages/django/core/handlers/base.py", line 98, in get_response
    resolver_match = resolver.resolve(request.path_info)
  File "/Users/abhishek.ranjan/virtualenvs/metastore/lib/python2.7/site-packages/django/core/urlresolvers.py", line 343, in resolve
    for pattern in self.url_patterns:
  File "/Users/abhishek.ranjan/virtualenvs/metastore/lib/python2.7/site-packages/django/core/urlresolvers.py", line 372, in url_patterns
    patterns = getattr(self.urlconf_module, "urlpatterns", self.urlconf_module)
  File "/Users/abhishek.ranjan/virtualenvs/metastore/lib/python2.7/site-packages/django/core/urlresolvers.py", line 366, in urlconf_module
    self._urlconf_module = import_module(self.urlconf_name)
  File "/System/Library/Frameworks/Python.framework/Versions/2.7/lib/python2.7/importlib/__init__.py", line 37, in import_module
    __import__(name)
  File "/Users/abhishek.ranjan/lols/metastore/metastore/urls.py", line 21, in <module>
    v2_api.register(resources.ResourceTypeResource())
AttributeError: 'module' object has no attribute 'ResourceTypeResource'
ERROR 2017-02-14 15:58:03,529 base 38268 4341288960 Internal Server Error: /favicon.ico
Traceback (most recent call last):
  File "/Users/abhishek.ranjan/virtualenvs/metastore/lib/python2.7/site-packages/django/core/handlers/base.py", line 87, in get_response
    response = middleware_method(request)
  File "/Users/abhishek.ranjan/virtualenvs/metastore/lib/python2.7/site-packages/django/middleware/common.py", line 72, in process_request
    if (not urlresolvers.is_valid_path(request.path_info, urlconf) and
  File "/Users/abhishek.ranjan/virtualenvs/metastore/lib/python2.7/site-packages/django/core/urlresolvers.py", line 619, in is_valid_path
    resolve(path, urlconf)
  File "/Users/abhishek.ranjan/virtualenvs/metastore/lib/python2.7/site-packages/django/core/urlresolvers.py", line 494, in resolve
    return get_resolver(urlconf).resolve(path)
  File "/Users/abhishek.ranjan/virtualenvs/metastore/lib/python2.7/site-packages/django/core/urlresolvers.py", line 343, in resolve
    for pattern in self.url_patterns:
  File "/Users/abhishek.ranjan/virtualenvs/metastore/lib/python2.7/site-packages/django/core/urlresolvers.py", line 372, in url_patterns
    patterns = getattr(self.urlconf_module, "urlpatterns", self.urlconf_module)
  File "/Users/abhishek.ranjan/virtualenvs/metastore/lib/python2.7/site-packages/django/core/urlresolvers.py", line 366, in urlconf_module
    self._urlconf_module = import_module(self.urlconf_name)
  File "/System/Library/Frameworks/Python.framework/Versions/2.7/lib/python2.7/importlib/__init__.py", line 37, in import_module
    __import__(name)
  File "/Users/abhishek.ranjan/lols/metastore/metastore/urls.py", line 21, in <module>
    v2_api.register(resources.ResourceTypeResource())
AttributeError: 'module' object has no attribute 'ResourceTypeResource'
ERROR 2017-02-14 15:58:06,611 base 38268 4341288960 Internal Server Error: /
Traceback (most recent call last):
  File "/Users/abhishek.ranjan/virtualenvs/metastore/lib/python2.7/site-packages/django/core/handlers/base.py", line 98, in get_response
    resolver_match = resolver.resolve(request.path_info)
  File "/Users/abhishek.ranjan/virtualenvs/metastore/lib/python2.7/site-packages/django/core/urlresolvers.py", line 343, in resolve
    for pattern in self.url_patterns:
  File "/Users/abhishek.ranjan/virtualenvs/metastore/lib/python2.7/site-packages/django/core/urlresolvers.py", line 372, in url_patterns
    patterns = getattr(self.urlconf_module, "urlpatterns", self.urlconf_module)
  File "/Users/abhishek.ranjan/virtualenvs/metastore/lib/python2.7/site-packages/django/core/urlresolvers.py", line 366, in urlconf_module
    self._urlconf_module = import_module(self.urlconf_name)
  File "/System/Library/Frameworks/Python.framework/Versions/2.7/lib/python2.7/importlib/__init__.py", line 37, in import_module
    __import__(name)
  File "/Users/abhishek.ranjan/lols/metastore/metastore/urls.py", line 21, in <module>
    v2_api.register(resources.ResourceTypeResource())
AttributeError: 'module' object has no attribute 'ResourceTypeResource'
ERROR 2017-02-14 15:58:06,889 base 38268 4341288960 Internal Server Error: /favicon.ico
Traceback (most recent call last):
  File "/Users/abhishek.ranjan/virtualenvs/metastore/lib/python2.7/site-packages/django/core/handlers/base.py", line 87, in get_response
    response = middleware_method(request)
  File "/Users/abhishek.ranjan/virtualenvs/metastore/lib/python2.7/site-packages/django/middleware/common.py", line 72, in process_request
    if (not urlresolvers.is_valid_path(request.path_info, urlconf) and
  File "/Users/abhishek.ranjan/virtualenvs/metastore/lib/python2.7/site-packages/django/core/urlresolvers.py", line 619, in is_valid_path
    resolve(path, urlconf)
  File "/Users/abhishek.ranjan/virtualenvs/metastore/lib/python2.7/site-packages/django/core/urlresolvers.py", line 494, in resolve
    return get_resolver(urlconf).resolve(path)
  File "/Users/abhishek.ranjan/virtualenvs/metastore/lib/python2.7/site-packages/django/core/urlresolvers.py", line 343, in resolve
    for pattern in self.url_patterns:
  File "/Users/abhishek.ranjan/virtualenvs/metastore/lib/python2.7/site-packages/django/core/urlresolvers.py", line 372, in url_patterns
    patterns = getattr(self.urlconf_module, "urlpatterns", self.urlconf_module)
  File "/Users/abhishek.ranjan/virtualenvs/metastore/lib/python2.7/site-packages/django/core/urlresolvers.py", line 366, in urlconf_module
    self._urlconf_module = import_module(self.urlconf_name)
  File "/System/Library/Frameworks/Python.framework/Versions/2.7/lib/python2.7/importlib/__init__.py", line 37, in import_module
    __import__(name)
  File "/Users/abhishek.ranjan/lols/metastore/metastore/urls.py", line 21, in <module>
    v2_api.register(resources.ResourceTypeResource())
AttributeError: 'module' object has no attribute 'ResourceTypeResource'
ERROR 2017-02-14 15:58:51,925 base 38383 4354195456 Internal Server Error: /admin/login/
Traceback (most recent call last):
  File "/Users/abhishek.ranjan/virtualenvs/metastore/lib/python2.7/site-packages/django/core/handlers/base.py", line 111, in get_response
    response = wrapped_callback(request, *callback_args, **callback_kwargs)
  File "/Users/abhishek.ranjan/virtualenvs/metastore/lib/python2.7/site-packages/django/views/decorators/cache.py", line 52, in _wrapped_view_func
    response = view_func(request, *args, **kwargs)
  File "/Users/abhishek.ranjan/virtualenvs/metastore/lib/python2.7/site-packages/django/contrib/admin/sites.py", line 361, in login
    return login(request, **defaults)
  File "/Users/abhishek.ranjan/virtualenvs/metastore/lib/python2.7/site-packages/django/views/decorators/debug.py", line 76, in sensitive_post_parameters_wrapper
    return view(request, *args, **kwargs)
  File "/Users/abhishek.ranjan/virtualenvs/metastore/lib/python2.7/site-packages/django/utils/decorators.py", line 105, in _wrapped_view
    response = view_func(request, *args, **kwargs)
  File "/Users/abhishek.ranjan/virtualenvs/metastore/lib/python2.7/site-packages/django/views/decorators/cache.py", line 52, in _wrapped_view_func
    response = view_func(request, *args, **kwargs)
  File "/Users/abhishek.ranjan/virtualenvs/metastore/lib/python2.7/site-packages/django/contrib/auth/views.py", line 37, in login
    if form.is_valid():
  File "/Users/abhishek.ranjan/virtualenvs/metastore/lib/python2.7/site-packages/django/forms/forms.py", line 162, in is_valid
    return self.is_bound and not bool(self.errors)
  File "/Users/abhishek.ranjan/virtualenvs/metastore/lib/python2.7/site-packages/django/forms/forms.py", line 154, in errors
    self.full_clean()
  File "/Users/abhishek.ranjan/virtualenvs/metastore/lib/python2.7/site-packages/django/forms/forms.py", line 354, in full_clean
    self._clean_form()
  File "/Users/abhishek.ranjan/virtualenvs/metastore/lib/python2.7/site-packages/django/forms/forms.py", line 378, in _clean_form
    cleaned_data = self.clean()
  File "/Users/abhishek.ranjan/virtualenvs/metastore/lib/python2.7/site-packages/django/contrib/auth/forms.py", line 192, in clean
    password=password)
  File "/Users/abhishek.ranjan/virtualenvs/metastore/lib/python2.7/site-packages/django/contrib/auth/__init__.py", line 60, in authenticate
    user = backend.authenticate(**credentials)
  File "/Users/abhishek.ranjan/virtualenvs/metastore/lib/python2.7/site-packages/django/contrib/auth/backends.py", line 16, in authenticate
    user = UserModel._default_manager.get_by_natural_key(username)
  File "/Users/abhishek.ranjan/virtualenvs/metastore/lib/python2.7/site-packages/django/contrib/auth/models.py", line 159, in get_by_natural_key
    return self.get(**{self.model.USERNAME_FIELD: username})
  File "/Users/abhishek.ranjan/virtualenvs/metastore/lib/python2.7/site-packages/django/db/models/manager.py", line 92, in manager_method
    return getattr(self.get_queryset(), name)(*args, **kwargs)
  File "/Users/abhishek.ranjan/virtualenvs/metastore/lib/python2.7/site-packages/django/db/models/query.py", line 351, in get
    num = len(clone)
  File "/Users/abhishek.ranjan/virtualenvs/metastore/lib/python2.7/site-packages/django/db/models/query.py", line 122, in __len__
    self._fetch_all()
  File "/Users/abhishek.ranjan/virtualenvs/metastore/lib/python2.7/site-packages/django/db/models/query.py", line 966, in _fetch_all
    self._result_cache = list(self.iterator())
  File "/Users/abhishek.ranjan/virtualenvs/metastore/lib/python2.7/site-packages/django/db/models/query.py", line 265, in iterator
    for row in compiler.results_iter():
  File "/Users/abhishek.ranjan/virtualenvs/metastore/lib/python2.7/site-packages/django/db/models/sql/compiler.py", line 700, in results_iter
    for rows in self.execute_sql(MULTI):
  File "/Users/abhishek.ranjan/virtualenvs/metastore/lib/python2.7/site-packages/django/db/models/sql/compiler.py", line 786, in execute_sql
    cursor.execute(sql, params)
  File "/Users/abhishek.ranjan/virtualenvs/metastore/lib/python2.7/site-packages/django/db/backends/utils.py", line 81, in execute
    return super(CursorDebugWrapper, self).execute(sql, params)
  File "/Users/abhishek.ranjan/virtualenvs/metastore/lib/python2.7/site-packages/django/db/backends/utils.py", line 65, in execute
    return self.cursor.execute(sql, params)
  File "/Users/abhishek.ranjan/virtualenvs/metastore/lib/python2.7/site-packages/django/db/utils.py", line 94, in __exit__
    six.reraise(dj_exc_type, dj_exc_value, traceback)
  File "/Users/abhishek.ranjan/virtualenvs/metastore/lib/python2.7/site-packages/django/db/backends/utils.py", line 65, in execute
    return self.cursor.execute(sql, params)
  File "/Users/abhishek.ranjan/virtualenvs/metastore/lib/python2.7/site-packages/django/db/backends/mysql/base.py", line 129, in execute
    return self.cursor.execute(query, args)
  File "/Users/abhishek.ranjan/virtualenvs/metastore/lib/python2.7/site-packages/MySQLdb/cursors.py", line 205, in execute
    self.errorhandler(self, exc, value)
  File "/Users/abhishek.ranjan/virtualenvs/metastore/lib/python2.7/site-packages/MySQLdb/connections.py", line 36, in defaulterrorhandler
    raise errorclass, errorvalue
ProgrammingError: (1146, "Table 'lols.auth_user' doesn't exist")
ERROR 2017-02-14 16:03:17,870 base 38586 4387115008 Internal Server Error: /admin/metastore/videos/add/
Traceback (most recent call last):
  File "/Users/abhishek.ranjan/virtualenvs/metastore/lib/python2.7/site-packages/django/core/handlers/base.py", line 111, in get_response
    response = wrapped_callback(request, *callback_args, **callback_kwargs)
  File "/Users/abhishek.ranjan/virtualenvs/metastore/lib/python2.7/site-packages/django/contrib/admin/options.py", line 583, in wrapper
    return self.admin_site.admin_view(view)(*args, **kwargs)
  File "/Users/abhishek.ranjan/virtualenvs/metastore/lib/python2.7/site-packages/django/utils/decorators.py", line 105, in _wrapped_view
    response = view_func(request, *args, **kwargs)
  File "/Users/abhishek.ranjan/virtualenvs/metastore/lib/python2.7/site-packages/django/views/decorators/cache.py", line 52, in _wrapped_view_func
    response = view_func(request, *args, **kwargs)
  File "/Users/abhishek.ranjan/virtualenvs/metastore/lib/python2.7/site-packages/django/contrib/admin/sites.py", line 206, in inner
    return view(request, *args, **kwargs)
  File "/Users/abhishek.ranjan/virtualenvs/metastore/lib/python2.7/site-packages/django/contrib/admin/options.py", line 1453, in add_view
    return self.changeform_view(request, None, form_url, extra_context)
  File "/Users/abhishek.ranjan/virtualenvs/metastore/lib/python2.7/site-packages/django/utils/decorators.py", line 29, in _wrapper
    return bound_func(*args, **kwargs)
  File "/Users/abhishek.ranjan/virtualenvs/metastore/lib/python2.7/site-packages/django/utils/decorators.py", line 105, in _wrapped_view
    response = view_func(request, *args, **kwargs)
  File "/Users/abhishek.ranjan/virtualenvs/metastore/lib/python2.7/site-packages/django/utils/decorators.py", line 25, in bound_func
    return func.__get__(self, type(self))(*args2, **kwargs2)
  File "/Users/abhishek.ranjan/virtualenvs/metastore/lib/python2.7/site-packages/django/db/transaction.py", line 394, in inner
    return func(*args, **kwargs)
  File "/Users/abhishek.ranjan/virtualenvs/metastore/lib/python2.7/site-packages/django/contrib/admin/options.py", line 1404, in changeform_view
    self.save_model(request, new_object, form, not add)
  File "/Users/abhishek.ranjan/virtualenvs/metastore/lib/python2.7/site-packages/django/contrib/admin/options.py", line 1045, in save_model
    obj.save()
  File "/Users/abhishek.ranjan/lols/metastore/metastore/models.py", line 52, in save
    super(Videos, self).save(*args, **kwargs)
  File "/Users/abhishek.ranjan/virtualenvs/metastore/lib/python2.7/site-packages/django/db/models/base.py", line 589, in save
    force_update=force_update, update_fields=update_fields)
  File "/Users/abhishek.ranjan/virtualenvs/metastore/lib/python2.7/site-packages/django/db/models/base.py", line 617, in save_base
    updated = self._save_table(raw, cls, force_insert, force_update, using, update_fields)
  File "/Users/abhishek.ranjan/virtualenvs/metastore/lib/python2.7/site-packages/django/db/models/base.py", line 698, in _save_table
    result = self._do_insert(cls._base_manager, using, fields, update_pk, raw)
  File "/Users/abhishek.ranjan/virtualenvs/metastore/lib/python2.7/site-packages/django/db/models/base.py", line 731, in _do_insert
    using=using, raw=raw)
  File "/Users/abhishek.ranjan/virtualenvs/metastore/lib/python2.7/site-packages/django/db/models/manager.py", line 92, in manager_method
    return getattr(self.get_queryset(), name)(*args, **kwargs)
  File "/Users/abhishek.ranjan/virtualenvs/metastore/lib/python2.7/site-packages/django/db/models/query.py", line 921, in _insert
    return query.get_compiler(using=using).execute_sql(return_id)
  File "/Users/abhishek.ranjan/virtualenvs/metastore/lib/python2.7/site-packages/django/db/models/sql/compiler.py", line 920, in execute_sql
    cursor.execute(sql, params)
  File "/Users/abhishek.ranjan/virtualenvs/metastore/lib/python2.7/site-packages/django/db/backends/utils.py", line 81, in execute
    return super(CursorDebugWrapper, self).execute(sql, params)
  File "/Users/abhishek.ranjan/virtualenvs/metastore/lib/python2.7/site-packages/django/db/backends/utils.py", line 65, in execute
    return self.cursor.execute(sql, params)
  File "/Users/abhishek.ranjan/virtualenvs/metastore/lib/python2.7/site-packages/django/db/backends/mysql/base.py", line 134, in execute
    six.reraise(utils.IntegrityError, utils.IntegrityError(*tuple(e.args)), sys.exc_info()[2])
  File "/Users/abhishek.ranjan/virtualenvs/metastore/lib/python2.7/site-packages/django/db/backends/mysql/base.py", line 129, in execute
    return self.cursor.execute(query, args)
  File "/Users/abhishek.ranjan/virtualenvs/metastore/lib/python2.7/site-packages/MySQLdb/cursors.py", line 205, in execute
    self.errorhandler(self, exc, value)
  File "/Users/abhishek.ranjan/virtualenvs/metastore/lib/python2.7/site-packages/MySQLdb/connections.py", line 36, in defaulterrorhandler
    raise errorclass, errorvalue
IntegrityError: (1048, "Column 'views' cannot be null")
ERROR 2017-02-14 16:03:38,416 base 38606 4586524672 Internal Server Error: /admin/metastore/videos/add/
Traceback (most recent call last):
  File "/Users/abhishek.ranjan/virtualenvs/metastore/lib/python2.7/site-packages/django/core/handlers/base.py", line 111, in get_response
    response = wrapped_callback(request, *callback_args, **callback_kwargs)
  File "/Users/abhishek.ranjan/virtualenvs/metastore/lib/python2.7/site-packages/django/contrib/admin/options.py", line 583, in wrapper
    return self.admin_site.admin_view(view)(*args, **kwargs)
  File "/Users/abhishek.ranjan/virtualenvs/metastore/lib/python2.7/site-packages/django/utils/decorators.py", line 105, in _wrapped_view
    response = view_func(request, *args, **kwargs)
  File "/Users/abhishek.ranjan/virtualenvs/metastore/lib/python2.7/site-packages/django/views/decorators/cache.py", line 52, in _wrapped_view_func
    response = view_func(request, *args, **kwargs)
  File "/Users/abhishek.ranjan/virtualenvs/metastore/lib/python2.7/site-packages/django/contrib/admin/sites.py", line 206, in inner
    return view(request, *args, **kwargs)
  File "/Users/abhishek.ranjan/virtualenvs/metastore/lib/python2.7/site-packages/django/contrib/admin/options.py", line 1453, in add_view
    return self.changeform_view(request, None, form_url, extra_context)
  File "/Users/abhishek.ranjan/virtualenvs/metastore/lib/python2.7/site-packages/django/utils/decorators.py", line 29, in _wrapper
    return bound_func(*args, **kwargs)
  File "/Users/abhishek.ranjan/virtualenvs/metastore/lib/python2.7/site-packages/django/utils/decorators.py", line 105, in _wrapped_view
    response = view_func(request, *args, **kwargs)
  File "/Users/abhishek.ranjan/virtualenvs/metastore/lib/python2.7/site-packages/django/utils/decorators.py", line 25, in bound_func
    return func.__get__(self, type(self))(*args2, **kwargs2)
  File "/Users/abhishek.ranjan/virtualenvs/metastore/lib/python2.7/site-packages/django/db/transaction.py", line 394, in inner
    return func(*args, **kwargs)
  File "/Users/abhishek.ranjan/virtualenvs/metastore/lib/python2.7/site-packages/django/contrib/admin/options.py", line 1404, in changeform_view
    self.save_model(request, new_object, form, not add)
  File "/Users/abhishek.ranjan/virtualenvs/metastore/lib/python2.7/site-packages/django/contrib/admin/options.py", line 1045, in save_model
    obj.save()
  File "/Users/abhishek.ranjan/lols/metastore/metastore/models.py", line 52, in save
    super(Videos, self).save(*args, **kwargs)
  File "/Users/abhishek.ranjan/virtualenvs/metastore/lib/python2.7/site-packages/django/db/models/base.py", line 589, in save
    force_update=force_update, update_fields=update_fields)
  File "/Users/abhishek.ranjan/virtualenvs/metastore/lib/python2.7/site-packages/django/db/models/base.py", line 617, in save_base
    updated = self._save_table(raw, cls, force_insert, force_update, using, update_fields)
  File "/Users/abhishek.ranjan/virtualenvs/metastore/lib/python2.7/site-packages/django/db/models/base.py", line 698, in _save_table
    result = self._do_insert(cls._base_manager, using, fields, update_pk, raw)
  File "/Users/abhishek.ranjan/virtualenvs/metastore/lib/python2.7/site-packages/django/db/models/base.py", line 731, in _do_insert
    using=using, raw=raw)
  File "/Users/abhishek.ranjan/virtualenvs/metastore/lib/python2.7/site-packages/django/db/models/manager.py", line 92, in manager_method
    return getattr(self.get_queryset(), name)(*args, **kwargs)
  File "/Users/abhishek.ranjan/virtualenvs/metastore/lib/python2.7/site-packages/django/db/models/query.py", line 921, in _insert
    return query.get_compiler(using=using).execute_sql(return_id)
  File "/Users/abhishek.ranjan/virtualenvs/metastore/lib/python2.7/site-packages/django/db/models/sql/compiler.py", line 920, in execute_sql
    cursor.execute(sql, params)
  File "/Users/abhishek.ranjan/virtualenvs/metastore/lib/python2.7/site-packages/django/db/backends/utils.py", line 81, in execute
    return super(CursorDebugWrapper, self).execute(sql, params)
  File "/Users/abhishek.ranjan/virtualenvs/metastore/lib/python2.7/site-packages/django/db/backends/utils.py", line 65, in execute
    return self.cursor.execute(sql, params)
  File "/Users/abhishek.ranjan/virtualenvs/metastore/lib/python2.7/site-packages/django/db/backends/mysql/base.py", line 134, in execute
    six.reraise(utils.IntegrityError, utils.IntegrityError(*tuple(e.args)), sys.exc_info()[2])
  File "/Users/abhishek.ranjan/virtualenvs/metastore/lib/python2.7/site-packages/django/db/backends/mysql/base.py", line 129, in execute
    return self.cursor.execute(query, args)
  File "/Users/abhishek.ranjan/virtualenvs/metastore/lib/python2.7/site-packages/MySQLdb/cursors.py", line 205, in execute
    self.errorhandler(self, exc, value)
  File "/Users/abhishek.ranjan/virtualenvs/metastore/lib/python2.7/site-packages/MySQLdb/connections.py", line 36, in defaulterrorhandler
    raise errorclass, errorvalue
IntegrityError: (1048, "Column 'views' cannot be null")
ERROR 2017-02-14 16:04:31,191 base 38639 4411887616 Internal Server Error: /admin/metastore/videos/add/
Traceback (most recent call last):
  File "/Users/abhishek.ranjan/virtualenvs/metastore/lib/python2.7/site-packages/django/core/handlers/base.py", line 111, in get_response
    response = wrapped_callback(request, *callback_args, **callback_kwargs)
  File "/Users/abhishek.ranjan/virtualenvs/metastore/lib/python2.7/site-packages/django/contrib/admin/options.py", line 583, in wrapper
    return self.admin_site.admin_view(view)(*args, **kwargs)
  File "/Users/abhishek.ranjan/virtualenvs/metastore/lib/python2.7/site-packages/django/utils/decorators.py", line 105, in _wrapped_view
    response = view_func(request, *args, **kwargs)
  File "/Users/abhishek.ranjan/virtualenvs/metastore/lib/python2.7/site-packages/django/views/decorators/cache.py", line 52, in _wrapped_view_func
    response = view_func(request, *args, **kwargs)
  File "/Users/abhishek.ranjan/virtualenvs/metastore/lib/python2.7/site-packages/django/contrib/admin/sites.py", line 206, in inner
    return view(request, *args, **kwargs)
  File "/Users/abhishek.ranjan/virtualenvs/metastore/lib/python2.7/site-packages/django/contrib/admin/options.py", line 1453, in add_view
    return self.changeform_view(request, None, form_url, extra_context)
  File "/Users/abhishek.ranjan/virtualenvs/metastore/lib/python2.7/site-packages/django/utils/decorators.py", line 29, in _wrapper
    return bound_func(*args, **kwargs)
  File "/Users/abhishek.ranjan/virtualenvs/metastore/lib/python2.7/site-packages/django/utils/decorators.py", line 105, in _wrapped_view
    response = view_func(request, *args, **kwargs)
  File "/Users/abhishek.ranjan/virtualenvs/metastore/lib/python2.7/site-packages/django/utils/decorators.py", line 25, in bound_func
    return func.__get__(self, type(self))(*args2, **kwargs2)
  File "/Users/abhishek.ranjan/virtualenvs/metastore/lib/python2.7/site-packages/django/db/transaction.py", line 394, in inner
    return func(*args, **kwargs)
  File "/Users/abhishek.ranjan/virtualenvs/metastore/lib/python2.7/site-packages/django/contrib/admin/options.py", line 1404, in changeform_view
    self.save_model(request, new_object, form, not add)
  File "/Users/abhishek.ranjan/virtualenvs/metastore/lib/python2.7/site-packages/django/contrib/admin/options.py", line 1045, in save_model
    obj.save()
  File "/Users/abhishek.ranjan/lols/metastore/metastore/models.py", line 52, in save
    super(Videos, self).save(*args, **kwargs)
  File "/Users/abhishek.ranjan/virtualenvs/metastore/lib/python2.7/site-packages/django/db/models/base.py", line 589, in save
    force_update=force_update, update_fields=update_fields)
  File "/Users/abhishek.ranjan/virtualenvs/metastore/lib/python2.7/site-packages/django/db/models/base.py", line 617, in save_base
    updated = self._save_table(raw, cls, force_insert, force_update, using, update_fields)
  File "/Users/abhishek.ranjan/virtualenvs/metastore/lib/python2.7/site-packages/django/db/models/base.py", line 698, in _save_table
    result = self._do_insert(cls._base_manager, using, fields, update_pk, raw)
  File "/Users/abhishek.ranjan/virtualenvs/metastore/lib/python2.7/site-packages/django/db/models/base.py", line 731, in _do_insert
    using=using, raw=raw)
  File "/Users/abhishek.ranjan/virtualenvs/metastore/lib/python2.7/site-packages/django/db/models/manager.py", line 92, in manager_method
    return getattr(self.get_queryset(), name)(*args, **kwargs)
  File "/Users/abhishek.ranjan/virtualenvs/metastore/lib/python2.7/site-packages/django/db/models/query.py", line 921, in _insert
    return query.get_compiler(using=using).execute_sql(return_id)
  File "/Users/abhishek.ranjan/virtualenvs/metastore/lib/python2.7/site-packages/django/db/models/sql/compiler.py", line 920, in execute_sql
    cursor.execute(sql, params)
  File "/Users/abhishek.ranjan/virtualenvs/metastore/lib/python2.7/site-packages/django/db/backends/utils.py", line 81, in execute
    return super(CursorDebugWrapper, self).execute(sql, params)
  File "/Users/abhishek.ranjan/virtualenvs/metastore/lib/python2.7/site-packages/django/db/backends/utils.py", line 65, in execute
    return self.cursor.execute(sql, params)
  File "/Users/abhishek.ranjan/virtualenvs/metastore/lib/python2.7/site-packages/django/db/backends/mysql/base.py", line 134, in execute
    six.reraise(utils.IntegrityError, utils.IntegrityError(*tuple(e.args)), sys.exc_info()[2])
  File "/Users/abhishek.ranjan/virtualenvs/metastore/lib/python2.7/site-packages/django/db/backends/mysql/base.py", line 129, in execute
    return self.cursor.execute(query, args)
  File "/Users/abhishek.ranjan/virtualenvs/metastore/lib/python2.7/site-packages/MySQLdb/cursors.py", line 205, in execute
    self.errorhandler(self, exc, value)
  File "/Users/abhishek.ranjan/virtualenvs/metastore/lib/python2.7/site-packages/MySQLdb/connections.py", line 36, in defaulterrorhandler
    raise errorclass, errorvalue
IntegrityError: (1048, "Column 'views' cannot be null")
ERROR 2017-02-14 16:05:11,463 base 38670 4579246080 Internal Server Error: /admin/metastore/videos/add/
Traceback (most recent call last):
  File "/Users/abhishek.ranjan/virtualenvs/metastore/lib/python2.7/site-packages/django/core/handlers/base.py", line 111, in get_response
    response = wrapped_callback(request, *callback_args, **callback_kwargs)
  File "/Users/abhishek.ranjan/virtualenvs/metastore/lib/python2.7/site-packages/django/contrib/admin/options.py", line 583, in wrapper
    return self.admin_site.admin_view(view)(*args, **kwargs)
  File "/Users/abhishek.ranjan/virtualenvs/metastore/lib/python2.7/site-packages/django/utils/decorators.py", line 105, in _wrapped_view
    response = view_func(request, *args, **kwargs)
  File "/Users/abhishek.ranjan/virtualenvs/metastore/lib/python2.7/site-packages/django/views/decorators/cache.py", line 52, in _wrapped_view_func
    response = view_func(request, *args, **kwargs)
  File "/Users/abhishek.ranjan/virtualenvs/metastore/lib/python2.7/site-packages/django/contrib/admin/sites.py", line 206, in inner
    return view(request, *args, **kwargs)
  File "/Users/abhishek.ranjan/virtualenvs/metastore/lib/python2.7/site-packages/django/contrib/admin/options.py", line 1453, in add_view
    return self.changeform_view(request, None, form_url, extra_context)
  File "/Users/abhishek.ranjan/virtualenvs/metastore/lib/python2.7/site-packages/django/utils/decorators.py", line 29, in _wrapper
    return bound_func(*args, **kwargs)
  File "/Users/abhishek.ranjan/virtualenvs/metastore/lib/python2.7/site-packages/django/utils/decorators.py", line 105, in _wrapped_view
    response = view_func(request, *args, **kwargs)
  File "/Users/abhishek.ranjan/virtualenvs/metastore/lib/python2.7/site-packages/django/utils/decorators.py", line 25, in bound_func
    return func.__get__(self, type(self))(*args2, **kwargs2)
  File "/Users/abhishek.ranjan/virtualenvs/metastore/lib/python2.7/site-packages/django/db/transaction.py", line 394, in inner
    return func(*args, **kwargs)
  File "/Users/abhishek.ranjan/virtualenvs/metastore/lib/python2.7/site-packages/django/contrib/admin/options.py", line 1407, in changeform_view
    self.log_addition(request, new_object)
  File "/Users/abhishek.ranjan/virtualenvs/metastore/lib/python2.7/site-packages/django/contrib/admin/options.py", line 776, in log_addition
    object_repr=force_text(object),
  File "/Users/abhishek.ranjan/virtualenvs/metastore/lib/python2.7/site-packages/django/utils/encoding.py", line 85, in force_text
    s = six.text_type(s)
  File "/Users/abhishek.ranjan/lols/metastore/metastore/models.py", line 47, in __unicode__
    return self.component_name
AttributeError: 'Videos' object has no attribute 'component_name'
ERROR 2017-02-14 16:05:30,200 base 38697 4531449856 Internal Server Error: /admin/metastore/videos/add/
Traceback (most recent call last):
  File "/Users/abhishek.ranjan/virtualenvs/metastore/lib/python2.7/site-packages/django/core/handlers/base.py", line 111, in get_response
    response = wrapped_callback(request, *callback_args, **callback_kwargs)
  File "/Users/abhishek.ranjan/virtualenvs/metastore/lib/python2.7/site-packages/django/contrib/admin/options.py", line 583, in wrapper
    return self.admin_site.admin_view(view)(*args, **kwargs)
  File "/Users/abhishek.ranjan/virtualenvs/metastore/lib/python2.7/site-packages/django/utils/decorators.py", line 105, in _wrapped_view
    response = view_func(request, *args, **kwargs)
  File "/Users/abhishek.ranjan/virtualenvs/metastore/lib/python2.7/site-packages/django/views/decorators/cache.py", line 52, in _wrapped_view_func
    response = view_func(request, *args, **kwargs)
  File "/Users/abhishek.ranjan/virtualenvs/metastore/lib/python2.7/site-packages/django/contrib/admin/sites.py", line 206, in inner
    return view(request, *args, **kwargs)
  File "/Users/abhishek.ranjan/virtualenvs/metastore/lib/python2.7/site-packages/django/contrib/admin/options.py", line 1453, in add_view
    return self.changeform_view(request, None, form_url, extra_context)
  File "/Users/abhishek.ranjan/virtualenvs/metastore/lib/python2.7/site-packages/django/utils/decorators.py", line 29, in _wrapper
    return bound_func(*args, **kwargs)
  File "/Users/abhishek.ranjan/virtualenvs/metastore/lib/python2.7/site-packages/django/utils/decorators.py", line 105, in _wrapped_view
    response = view_func(request, *args, **kwargs)
  File "/Users/abhishek.ranjan/virtualenvs/metastore/lib/python2.7/site-packages/django/utils/decorators.py", line 25, in bound_func
    return func.__get__(self, type(self))(*args2, **kwargs2)
  File "/Users/abhishek.ranjan/virtualenvs/metastore/lib/python2.7/site-packages/django/db/transaction.py", line 394, in inner
    return func(*args, **kwargs)
  File "/Users/abhishek.ranjan/virtualenvs/metastore/lib/python2.7/site-packages/django/contrib/admin/options.py", line 1407, in changeform_view
    self.log_addition(request, new_object)
  File "/Users/abhishek.ranjan/virtualenvs/metastore/lib/python2.7/site-packages/django/contrib/admin/options.py", line 776, in log_addition
    object_repr=force_text(object),
  File "/Users/abhishek.ranjan/virtualenvs/metastore/lib/python2.7/site-packages/django/utils/encoding.py", line 85, in force_text
    s = six.text_type(s)
TypeError: coercing to Unicode: need string or buffer, long found
ERROR 2017-02-14 16:06:54,933 base 38697 4531449856 Internal Server Error: /admin/metastore/videos/add/
Traceback (most recent call last):
  File "/Users/abhishek.ranjan/virtualenvs/metastore/lib/python2.7/site-packages/django/core/handlers/base.py", line 111, in get_response
    response = wrapped_callback(request, *callback_args, **callback_kwargs)
  File "/Users/abhishek.ranjan/virtualenvs/metastore/lib/python2.7/site-packages/django/contrib/admin/options.py", line 583, in wrapper
    return self.admin_site.admin_view(view)(*args, **kwargs)
  File "/Users/abhishek.ranjan/virtualenvs/metastore/lib/python2.7/site-packages/django/utils/decorators.py", line 105, in _wrapped_view
    response = view_func(request, *args, **kwargs)
  File "/Users/abhishek.ranjan/virtualenvs/metastore/lib/python2.7/site-packages/django/views/decorators/cache.py", line 52, in _wrapped_view_func
    response = view_func(request, *args, **kwargs)
  File "/Users/abhishek.ranjan/virtualenvs/metastore/lib/python2.7/site-packages/django/contrib/admin/sites.py", line 206, in inner
    return view(request, *args, **kwargs)
  File "/Users/abhishek.ranjan/virtualenvs/metastore/lib/python2.7/site-packages/django/contrib/admin/options.py", line 1453, in add_view
    return self.changeform_view(request, None, form_url, extra_context)
  File "/Users/abhishek.ranjan/virtualenvs/metastore/lib/python2.7/site-packages/django/utils/decorators.py", line 29, in _wrapper
    return bound_func(*args, **kwargs)
  File "/Users/abhishek.ranjan/virtualenvs/metastore/lib/python2.7/site-packages/django/utils/decorators.py", line 105, in _wrapped_view
    response = view_func(request, *args, **kwargs)
  File "/Users/abhishek.ranjan/virtualenvs/metastore/lib/python2.7/site-packages/django/utils/decorators.py", line 25, in bound_func
    return func.__get__(self, type(self))(*args2, **kwargs2)
  File "/Users/abhishek.ranjan/virtualenvs/metastore/lib/python2.7/site-packages/django/db/transaction.py", line 394, in inner
    return func(*args, **kwargs)
  File "/Users/abhishek.ranjan/virtualenvs/metastore/lib/python2.7/site-packages/django/contrib/admin/options.py", line 1407, in changeform_view
    self.log_addition(request, new_object)
  File "/Users/abhishek.ranjan/virtualenvs/metastore/lib/python2.7/site-packages/django/contrib/admin/options.py", line 776, in log_addition
    object_repr=force_text(object),
  File "/Users/abhishek.ranjan/virtualenvs/metastore/lib/python2.7/site-packages/django/utils/encoding.py", line 85, in force_text
    s = six.text_type(s)
TypeError: coercing to Unicode: need string or buffer, long found
ERROR 2017-02-16 08:44:37,419 base 38804 4406788096 Internal Server Error: /admin
Traceback (most recent call last):
  File "/Users/abhishek.ranjan/virtualenvs/metastore/lib/python2.7/site-packages/django/core/handlers/base.py", line 87, in get_response
    response = middleware_method(request)
  File "/Users/abhishek.ranjan/virtualenvs/metastore/lib/python2.7/site-packages/django/middleware/common.py", line 72, in process_request
    if (not urlresolvers.is_valid_path(request.path_info, urlconf) and
  File "/Users/abhishek.ranjan/virtualenvs/metastore/lib/python2.7/site-packages/django/core/urlresolvers.py", line 619, in is_valid_path
    resolve(path, urlconf)
  File "/Users/abhishek.ranjan/virtualenvs/metastore/lib/python2.7/site-packages/django/core/urlresolvers.py", line 494, in resolve
    return get_resolver(urlconf).resolve(path)
  File "/Users/abhishek.ranjan/virtualenvs/metastore/lib/python2.7/site-packages/django/core/urlresolvers.py", line 343, in resolve
    for pattern in self.url_patterns:
  File "/Users/abhishek.ranjan/virtualenvs/metastore/lib/python2.7/site-packages/django/core/urlresolvers.py", line 372, in url_patterns
    patterns = getattr(self.urlconf_module, "urlpatterns", self.urlconf_module)
  File "/Users/abhishek.ranjan/virtualenvs/metastore/lib/python2.7/site-packages/django/core/urlresolvers.py", line 366, in urlconf_module
    self._urlconf_module = import_module(self.urlconf_name)
  File "/System/Library/Frameworks/Python.framework/Versions/2.7/lib/python2.7/importlib/__init__.py", line 37, in import_module
    __import__(name)
  File "/Users/abhishek.ranjan/lols/metastore/metastore/urls.py", line 35, in <module>
    url(r'^admin/compare/', views.diff_view, name='resource-diff-view'),
AttributeError: 'module' object has no attribute 'diff_view'
ERROR 2017-02-16 08:44:37,959 base 38804 4410994688 Internal Server Error: /favicon.ico
Traceback (most recent call last):
  File "/Users/abhishek.ranjan/virtualenvs/metastore/lib/python2.7/site-packages/django/core/handlers/base.py", line 87, in get_response
    response = middleware_method(request)
  File "/Users/abhishek.ranjan/virtualenvs/metastore/lib/python2.7/site-packages/django/middleware/common.py", line 72, in process_request
    if (not urlresolvers.is_valid_path(request.path_info, urlconf) and
  File "/Users/abhishek.ranjan/virtualenvs/metastore/lib/python2.7/site-packages/django/core/urlresolvers.py", line 619, in is_valid_path
    resolve(path, urlconf)
  File "/Users/abhishek.ranjan/virtualenvs/metastore/lib/python2.7/site-packages/django/core/urlresolvers.py", line 494, in resolve
    return get_resolver(urlconf).resolve(path)
  File "/Users/abhishek.ranjan/virtualenvs/metastore/lib/python2.7/site-packages/django/core/urlresolvers.py", line 343, in resolve
    for pattern in self.url_patterns:
  File "/Users/abhishek.ranjan/virtualenvs/metastore/lib/python2.7/site-packages/django/core/urlresolvers.py", line 372, in url_patterns
    patterns = getattr(self.urlconf_module, "urlpatterns", self.urlconf_module)
  File "/Users/abhishek.ranjan/virtualenvs/metastore/lib/python2.7/site-packages/django/core/urlresolvers.py", line 366, in urlconf_module
    self._urlconf_module = import_module(self.urlconf_name)
  File "/System/Library/Frameworks/Python.framework/Versions/2.7/lib/python2.7/importlib/__init__.py", line 37, in import_module
    __import__(name)
  File "/Users/abhishek.ranjan/lols/metastore/metastore/urls.py", line 35, in <module>
    url(r'^admin/compare/', views.diff_view, name='resource-diff-view'),
AttributeError: 'module' object has no attribute 'diff_view'
ERROR 2017-02-16 15:23:14,394 base 72397 4333432832 Internal Server Error: /admin/metastore/videos/2/
Traceback (most recent call last):
  File "/Users/abhishek.ranjan/virtualenvs/metastore/lib/python2.7/site-packages/django/core/handlers/base.py", line 137, in get_response
    response = response.render()
  File "/Users/abhishek.ranjan/virtualenvs/metastore/lib/python2.7/site-packages/django/template/response.py", line 103, in render
    self.content = self.rendered_content
  File "/Users/abhishek.ranjan/virtualenvs/metastore/lib/python2.7/site-packages/django/template/response.py", line 80, in rendered_content
    content = template.render(context)
  File "/Users/abhishek.ranjan/virtualenvs/metastore/lib/python2.7/site-packages/django/template/base.py", line 148, in render
    return self._render(context)
  File "/Users/abhishek.ranjan/virtualenvs/metastore/lib/python2.7/site-packages/django/template/base.py", line 142, in _render
    return self.nodelist.render(context)
  File "/Users/abhishek.ranjan/virtualenvs/metastore/lib/python2.7/site-packages/django/template/base.py", line 844, in render
    bit = self.render_node(node, context)
  File "/Users/abhishek.ranjan/virtualenvs/metastore/lib/python2.7/site-packages/django/template/debug.py", line 80, in render_node
    return node.render(context)
  File "/Users/abhishek.ranjan/virtualenvs/metastore/lib/python2.7/site-packages/django/template/loader_tags.py", line 126, in render
    return compiled_parent._render(context)
  File "/Users/abhishek.ranjan/virtualenvs/metastore/lib/python2.7/site-packages/django/template/base.py", line 142, in _render
    return self.nodelist.render(context)
  File "/Users/abhishek.ranjan/virtualenvs/metastore/lib/python2.7/site-packages/django/template/base.py", line 844, in render
    bit = self.render_node(node, context)
  File "/Users/abhishek.ranjan/virtualenvs/metastore/lib/python2.7/site-packages/django/template/debug.py", line 80, in render_node
    return node.render(context)
  File "/Users/abhishek.ranjan/virtualenvs/metastore/lib/python2.7/site-packages/django/template/loader_tags.py", line 126, in render
    return compiled_parent._render(context)
  File "/Users/abhishek.ranjan/virtualenvs/metastore/lib/python2.7/site-packages/django/template/base.py", line 142, in _render
    return self.nodelist.render(context)
  File "/Users/abhishek.ranjan/virtualenvs/metastore/lib/python2.7/site-packages/django/template/base.py", line 844, in render
    bit = self.render_node(node, context)
  File "/Users/abhishek.ranjan/virtualenvs/metastore/lib/python2.7/site-packages/django/template/debug.py", line 80, in render_node
    return node.render(context)
  File "/Users/abhishek.ranjan/virtualenvs/metastore/lib/python2.7/site-packages/django/template/loader_tags.py", line 65, in render
    result = block.nodelist.render(context)
  File "/Users/abhishek.ranjan/virtualenvs/metastore/lib/python2.7/site-packages/django/template/base.py", line 844, in render
    bit = self.render_node(node, context)
  File "/Users/abhishek.ranjan/virtualenvs/metastore/lib/python2.7/site-packages/django/template/debug.py", line 80, in render_node
    return node.render(context)
  File "/Users/abhishek.ranjan/virtualenvs/metastore/lib/python2.7/site-packages/django/template/defaulttags.py", line 458, in render
    six.reraise(*exc_info)
  File "/Users/abhishek.ranjan/virtualenvs/metastore/lib/python2.7/site-packages/django/template/defaulttags.py", line 444, in render
    url = reverse(view_name, args=args, kwargs=kwargs, current_app=context.current_app)
  File "/Users/abhishek.ranjan/virtualenvs/metastore/lib/python2.7/site-packages/django/core/urlresolvers.py", line 551, in reverse
    return iri_to_uri(resolver._reverse_with_prefix(view, prefix, *args, **kwargs))
  File "/Users/abhishek.ranjan/virtualenvs/metastore/lib/python2.7/site-packages/django/core/urlresolvers.py", line 468, in _reverse_with_prefix
    (lookup_view_s, args, kwargs, len(patterns), patterns))
NoReverseMatch: Reverse for 'grp_related_lookup' with arguments '()' and keyword arguments '{}' not found. 0 pattern(s) tried: []
ERROR 2017-02-16 15:23:27,754 base 72397 4333432832 Internal Server Error: /admin/metastore/videos/2/
Traceback (most recent call last):
  File "/Users/abhishek.ranjan/virtualenvs/metastore/lib/python2.7/site-packages/django/core/handlers/base.py", line 137, in get_response
    response = response.render()
  File "/Users/abhishek.ranjan/virtualenvs/metastore/lib/python2.7/site-packages/django/template/response.py", line 103, in render
    self.content = self.rendered_content
  File "/Users/abhishek.ranjan/virtualenvs/metastore/lib/python2.7/site-packages/django/template/response.py", line 80, in rendered_content
    content = template.render(context)
  File "/Users/abhishek.ranjan/virtualenvs/metastore/lib/python2.7/site-packages/django/template/base.py", line 148, in render
    return self._render(context)
  File "/Users/abhishek.ranjan/virtualenvs/metastore/lib/python2.7/site-packages/django/template/base.py", line 142, in _render
    return self.nodelist.render(context)
  File "/Users/abhishek.ranjan/virtualenvs/metastore/lib/python2.7/site-packages/django/template/base.py", line 844, in render
    bit = self.render_node(node, context)
  File "/Users/abhishek.ranjan/virtualenvs/metastore/lib/python2.7/site-packages/django/template/debug.py", line 80, in render_node
    return node.render(context)
  File "/Users/abhishek.ranjan/virtualenvs/metastore/lib/python2.7/site-packages/django/template/loader_tags.py", line 126, in render
    return compiled_parent._render(context)
  File "/Users/abhishek.ranjan/virtualenvs/metastore/lib/python2.7/site-packages/django/template/base.py", line 142, in _render
    return self.nodelist.render(context)
  File "/Users/abhishek.ranjan/virtualenvs/metastore/lib/python2.7/site-packages/django/template/base.py", line 844, in render
    bit = self.render_node(node, context)
  File "/Users/abhishek.ranjan/virtualenvs/metastore/lib/python2.7/site-packages/django/template/debug.py", line 80, in render_node
    return node.render(context)
  File "/Users/abhishek.ranjan/virtualenvs/metastore/lib/python2.7/site-packages/django/template/loader_tags.py", line 126, in render
    return compiled_parent._render(context)
  File "/Users/abhishek.ranjan/virtualenvs/metastore/lib/python2.7/site-packages/django/template/base.py", line 142, in _render
    return self.nodelist.render(context)
  File "/Users/abhishek.ranjan/virtualenvs/metastore/lib/python2.7/site-packages/django/template/base.py", line 844, in render
    bit = self.render_node(node, context)
  File "/Users/abhishek.ranjan/virtualenvs/metastore/lib/python2.7/site-packages/django/template/debug.py", line 80, in render_node
    return node.render(context)
  File "/Users/abhishek.ranjan/virtualenvs/metastore/lib/python2.7/site-packages/django/template/loader_tags.py", line 65, in render
    result = block.nodelist.render(context)
  File "/Users/abhishek.ranjan/virtualenvs/metastore/lib/python2.7/site-packages/django/template/base.py", line 844, in render
    bit = self.render_node(node, context)
  File "/Users/abhishek.ranjan/virtualenvs/metastore/lib/python2.7/site-packages/django/template/debug.py", line 80, in render_node
    return node.render(context)
  File "/Users/abhishek.ranjan/virtualenvs/metastore/lib/python2.7/site-packages/django/template/defaulttags.py", line 458, in render
    six.reraise(*exc_info)
  File "/Users/abhishek.ranjan/virtualenvs/metastore/lib/python2.7/site-packages/django/template/defaulttags.py", line 444, in render
    url = reverse(view_name, args=args, kwargs=kwargs, current_app=context.current_app)
  File "/Users/abhishek.ranjan/virtualenvs/metastore/lib/python2.7/site-packages/django/core/urlresolvers.py", line 551, in reverse
    return iri_to_uri(resolver._reverse_with_prefix(view, prefix, *args, **kwargs))
  File "/Users/abhishek.ranjan/virtualenvs/metastore/lib/python2.7/site-packages/django/core/urlresolvers.py", line 468, in _reverse_with_prefix
    (lookup_view_s, args, kwargs, len(patterns), patterns))
NoReverseMatch: Reverse for 'grp_related_lookup' with arguments '()' and keyword arguments '{}' not found. 0 pattern(s) tried: []
ERROR 2017-02-16 15:23:50,351 base 72459 4425011200 Internal Server Error: /admin/metastore/videos/2/
Traceback (most recent call last):
  File "/Users/abhishek.ranjan/virtualenvs/metastore/lib/python2.7/site-packages/django/core/handlers/base.py", line 137, in get_response
    response = response.render()
  File "/Users/abhishek.ranjan/virtualenvs/metastore/lib/python2.7/site-packages/django/template/response.py", line 103, in render
    self.content = self.rendered_content
  File "/Users/abhishek.ranjan/virtualenvs/metastore/lib/python2.7/site-packages/django/template/response.py", line 80, in rendered_content
    content = template.render(context)
  File "/Users/abhishek.ranjan/virtualenvs/metastore/lib/python2.7/site-packages/django/template/base.py", line 148, in render
    return self._render(context)
  File "/Users/abhishek.ranjan/virtualenvs/metastore/lib/python2.7/site-packages/django/template/base.py", line 142, in _render
    return self.nodelist.render(context)
  File "/Users/abhishek.ranjan/virtualenvs/metastore/lib/python2.7/site-packages/django/template/base.py", line 844, in render
    bit = self.render_node(node, context)
  File "/Users/abhishek.ranjan/virtualenvs/metastore/lib/python2.7/site-packages/django/template/debug.py", line 80, in render_node
    return node.render(context)
  File "/Users/abhishek.ranjan/virtualenvs/metastore/lib/python2.7/site-packages/django/template/loader_tags.py", line 126, in render
    return compiled_parent._render(context)
  File "/Users/abhishek.ranjan/virtualenvs/metastore/lib/python2.7/site-packages/django/template/base.py", line 142, in _render
    return self.nodelist.render(context)
  File "/Users/abhishek.ranjan/virtualenvs/metastore/lib/python2.7/site-packages/django/template/base.py", line 844, in render
    bit = self.render_node(node, context)
  File "/Users/abhishek.ranjan/virtualenvs/metastore/lib/python2.7/site-packages/django/template/debug.py", line 80, in render_node
    return node.render(context)
  File "/Users/abhishek.ranjan/virtualenvs/metastore/lib/python2.7/site-packages/django/template/loader_tags.py", line 126, in render
    return compiled_parent._render(context)
  File "/Users/abhishek.ranjan/virtualenvs/metastore/lib/python2.7/site-packages/django/template/base.py", line 142, in _render
    return self.nodelist.render(context)
  File "/Users/abhishek.ranjan/virtualenvs/metastore/lib/python2.7/site-packages/django/template/base.py", line 844, in render
    bit = self.render_node(node, context)
  File "/Users/abhishek.ranjan/virtualenvs/metastore/lib/python2.7/site-packages/django/template/debug.py", line 80, in render_node
    return node.render(context)
  File "/Users/abhishek.ranjan/virtualenvs/metastore/lib/python2.7/site-packages/django/template/loader_tags.py", line 65, in render
    result = block.nodelist.render(context)
  File "/Users/abhishek.ranjan/virtualenvs/metastore/lib/python2.7/site-packages/django/template/base.py", line 844, in render
    bit = self.render_node(node, context)
  File "/Users/abhishek.ranjan/virtualenvs/metastore/lib/python2.7/site-packages/django/template/debug.py", line 80, in render_node
    return node.render(context)
  File "/Users/abhishek.ranjan/virtualenvs/metastore/lib/python2.7/site-packages/django/template/defaulttags.py", line 458, in render
    six.reraise(*exc_info)
  File "/Users/abhishek.ranjan/virtualenvs/metastore/lib/python2.7/site-packages/django/template/defaulttags.py", line 444, in render
    url = reverse(view_name, args=args, kwargs=kwargs, current_app=context.current_app)
  File "/Users/abhishek.ranjan/virtualenvs/metastore/lib/python2.7/site-packages/django/core/urlresolvers.py", line 551, in reverse
    return iri_to_uri(resolver._reverse_with_prefix(view, prefix, *args, **kwargs))
  File "/Users/abhishek.ranjan/virtualenvs/metastore/lib/python2.7/site-packages/django/core/urlresolvers.py", line 468, in _reverse_with_prefix
    (lookup_view_s, args, kwargs, len(patterns), patterns))
NoReverseMatch: Reverse for 'grp_related_lookup' with arguments '()' and keyword arguments '{}' not found. 0 pattern(s) tried: []
ERROR 2017-02-16 15:23:59,919 base 72459 4425011200 Internal Server Error: /admin/metastore/videos/1/
Traceback (most recent call last):
  File "/Users/abhishek.ranjan/virtualenvs/metastore/lib/python2.7/site-packages/django/core/handlers/base.py", line 137, in get_response
    response = response.render()
  File "/Users/abhishek.ranjan/virtualenvs/metastore/lib/python2.7/site-packages/django/template/response.py", line 103, in render
    self.content = self.rendered_content
  File "/Users/abhishek.ranjan/virtualenvs/metastore/lib/python2.7/site-packages/django/template/response.py", line 80, in rendered_content
    content = template.render(context)
  File "/Users/abhishek.ranjan/virtualenvs/metastore/lib/python2.7/site-packages/django/template/base.py", line 148, in render
    return self._render(context)
  File "/Users/abhishek.ranjan/virtualenvs/metastore/lib/python2.7/site-packages/django/template/base.py", line 142, in _render
    return self.nodelist.render(context)
  File "/Users/abhishek.ranjan/virtualenvs/metastore/lib/python2.7/site-packages/django/template/base.py", line 844, in render
    bit = self.render_node(node, context)
  File "/Users/abhishek.ranjan/virtualenvs/metastore/lib/python2.7/site-packages/django/template/debug.py", line 80, in render_node
    return node.render(context)
  File "/Users/abhishek.ranjan/virtualenvs/metastore/lib/python2.7/site-packages/django/template/loader_tags.py", line 126, in render
    return compiled_parent._render(context)
  File "/Users/abhishek.ranjan/virtualenvs/metastore/lib/python2.7/site-packages/django/template/base.py", line 142, in _render
    return self.nodelist.render(context)
  File "/Users/abhishek.ranjan/virtualenvs/metastore/lib/python2.7/site-packages/django/template/base.py", line 844, in render
    bit = self.render_node(node, context)
  File "/Users/abhishek.ranjan/virtualenvs/metastore/lib/python2.7/site-packages/django/template/debug.py", line 80, in render_node
    return node.render(context)
  File "/Users/abhishek.ranjan/virtualenvs/metastore/lib/python2.7/site-packages/django/template/loader_tags.py", line 126, in render
    return compiled_parent._render(context)
  File "/Users/abhishek.ranjan/virtualenvs/metastore/lib/python2.7/site-packages/django/template/base.py", line 142, in _render
    return self.nodelist.render(context)
  File "/Users/abhishek.ranjan/virtualenvs/metastore/lib/python2.7/site-packages/django/template/base.py", line 844, in render
    bit = self.render_node(node, context)
  File "/Users/abhishek.ranjan/virtualenvs/metastore/lib/python2.7/site-packages/django/template/debug.py", line 80, in render_node
    return node.render(context)
  File "/Users/abhishek.ranjan/virtualenvs/metastore/lib/python2.7/site-packages/django/template/loader_tags.py", line 65, in render
    result = block.nodelist.render(context)
  File "/Users/abhishek.ranjan/virtualenvs/metastore/lib/python2.7/site-packages/django/template/base.py", line 844, in render
    bit = self.render_node(node, context)
  File "/Users/abhishek.ranjan/virtualenvs/metastore/lib/python2.7/site-packages/django/template/debug.py", line 80, in render_node
    return node.render(context)
  File "/Users/abhishek.ranjan/virtualenvs/metastore/lib/python2.7/site-packages/django/template/defaulttags.py", line 458, in render
    six.reraise(*exc_info)
  File "/Users/abhishek.ranjan/virtualenvs/metastore/lib/python2.7/site-packages/django/template/defaulttags.py", line 444, in render
    url = reverse(view_name, args=args, kwargs=kwargs, current_app=context.current_app)
  File "/Users/abhishek.ranjan/virtualenvs/metastore/lib/python2.7/site-packages/django/core/urlresolvers.py", line 551, in reverse
    return iri_to_uri(resolver._reverse_with_prefix(view, prefix, *args, **kwargs))
  File "/Users/abhishek.ranjan/virtualenvs/metastore/lib/python2.7/site-packages/django/core/urlresolvers.py", line 468, in _reverse_with_prefix
    (lookup_view_s, args, kwargs, len(patterns), patterns))
NoReverseMatch: Reverse for 'grp_related_lookup' with arguments '()' and keyword arguments '{}' not found. 0 pattern(s) tried: []
ERROR 2017-02-16 15:24:52,138 base 72505 4520022016 Internal Server Error: /admin/metastore/videos/1/
Traceback (most recent call last):
  File "/Users/abhishek.ranjan/virtualenvs/metastore/lib/python2.7/site-packages/django/core/handlers/base.py", line 137, in get_response
    response = response.render()
  File "/Users/abhishek.ranjan/virtualenvs/metastore/lib/python2.7/site-packages/django/template/response.py", line 103, in render
    self.content = self.rendered_content
  File "/Users/abhishek.ranjan/virtualenvs/metastore/lib/python2.7/site-packages/django/template/response.py", line 80, in rendered_content
    content = template.render(context)
  File "/Users/abhishek.ranjan/virtualenvs/metastore/lib/python2.7/site-packages/django/template/base.py", line 148, in render
    return self._render(context)
  File "/Users/abhishek.ranjan/virtualenvs/metastore/lib/python2.7/site-packages/django/template/base.py", line 142, in _render
    return self.nodelist.render(context)
  File "/Users/abhishek.ranjan/virtualenvs/metastore/lib/python2.7/site-packages/django/template/base.py", line 844, in render
    bit = self.render_node(node, context)
  File "/Users/abhishek.ranjan/virtualenvs/metastore/lib/python2.7/site-packages/django/template/debug.py", line 80, in render_node
    return node.render(context)
  File "/Users/abhishek.ranjan/virtualenvs/metastore/lib/python2.7/site-packages/django/template/loader_tags.py", line 126, in render
    return compiled_parent._render(context)
  File "/Users/abhishek.ranjan/virtualenvs/metastore/lib/python2.7/site-packages/django/template/base.py", line 142, in _render
    return self.nodelist.render(context)
  File "/Users/abhishek.ranjan/virtualenvs/metastore/lib/python2.7/site-packages/django/template/base.py", line 844, in render
    bit = self.render_node(node, context)
  File "/Users/abhishek.ranjan/virtualenvs/metastore/lib/python2.7/site-packages/django/template/debug.py", line 80, in render_node
    return node.render(context)
  File "/Users/abhishek.ranjan/virtualenvs/metastore/lib/python2.7/site-packages/django/template/loader_tags.py", line 126, in render
    return compiled_parent._render(context)
  File "/Users/abhishek.ranjan/virtualenvs/metastore/lib/python2.7/site-packages/django/template/base.py", line 142, in _render
    return self.nodelist.render(context)
  File "/Users/abhishek.ranjan/virtualenvs/metastore/lib/python2.7/site-packages/django/template/base.py", line 844, in render
    bit = self.render_node(node, context)
  File "/Users/abhishek.ranjan/virtualenvs/metastore/lib/python2.7/site-packages/django/template/debug.py", line 80, in render_node
    return node.render(context)
  File "/Users/abhishek.ranjan/virtualenvs/metastore/lib/python2.7/site-packages/django/template/loader_tags.py", line 65, in render
    result = block.nodelist.render(context)
  File "/Users/abhishek.ranjan/virtualenvs/metastore/lib/python2.7/site-packages/django/template/base.py", line 844, in render
    bit = self.render_node(node, context)
  File "/Users/abhishek.ranjan/virtualenvs/metastore/lib/python2.7/site-packages/django/template/debug.py", line 80, in render_node
    return node.render(context)
  File "/Users/abhishek.ranjan/virtualenvs/metastore/lib/python2.7/site-packages/django/template/defaulttags.py", line 458, in render
    six.reraise(*exc_info)
  File "/Users/abhishek.ranjan/virtualenvs/metastore/lib/python2.7/site-packages/django/template/defaulttags.py", line 444, in render
    url = reverse(view_name, args=args, kwargs=kwargs, current_app=context.current_app)
  File "/Users/abhishek.ranjan/virtualenvs/metastore/lib/python2.7/site-packages/django/core/urlresolvers.py", line 551, in reverse
    return iri_to_uri(resolver._reverse_with_prefix(view, prefix, *args, **kwargs))
  File "/Users/abhishek.ranjan/virtualenvs/metastore/lib/python2.7/site-packages/django/core/urlresolvers.py", line 468, in _reverse_with_prefix
    (lookup_view_s, args, kwargs, len(patterns), patterns))
NoReverseMatch: Reverse for 'grp_related_lookup' with arguments '()' and keyword arguments '{}' not found. 0 pattern(s) tried: []
ERROR 2017-02-16 15:24:56,098 base 72505 4524228608 Internal Server Error: /admin/metastore/videos/1/
Traceback (most recent call last):
  File "/Users/abhishek.ranjan/virtualenvs/metastore/lib/python2.7/site-packages/django/core/handlers/base.py", line 137, in get_response
    response = response.render()
  File "/Users/abhishek.ranjan/virtualenvs/metastore/lib/python2.7/site-packages/django/template/response.py", line 103, in render
    self.content = self.rendered_content
  File "/Users/abhishek.ranjan/virtualenvs/metastore/lib/python2.7/site-packages/django/template/response.py", line 80, in rendered_content
    content = template.render(context)
  File "/Users/abhishek.ranjan/virtualenvs/metastore/lib/python2.7/site-packages/django/template/base.py", line 148, in render
    return self._render(context)
  File "/Users/abhishek.ranjan/virtualenvs/metastore/lib/python2.7/site-packages/django/template/base.py", line 142, in _render
    return self.nodelist.render(context)
  File "/Users/abhishek.ranjan/virtualenvs/metastore/lib/python2.7/site-packages/django/template/base.py", line 844, in render
    bit = self.render_node(node, context)
  File "/Users/abhishek.ranjan/virtualenvs/metastore/lib/python2.7/site-packages/django/template/debug.py", line 80, in render_node
    return node.render(context)
  File "/Users/abhishek.ranjan/virtualenvs/metastore/lib/python2.7/site-packages/django/template/loader_tags.py", line 126, in render
    return compiled_parent._render(context)
  File "/Users/abhishek.ranjan/virtualenvs/metastore/lib/python2.7/site-packages/django/template/base.py", line 142, in _render
    return self.nodelist.render(context)
  File "/Users/abhishek.ranjan/virtualenvs/metastore/lib/python2.7/site-packages/django/template/base.py", line 844, in render
    bit = self.render_node(node, context)
  File "/Users/abhishek.ranjan/virtualenvs/metastore/lib/python2.7/site-packages/django/template/debug.py", line 80, in render_node
    return node.render(context)
  File "/Users/abhishek.ranjan/virtualenvs/metastore/lib/python2.7/site-packages/django/template/loader_tags.py", line 126, in render
    return compiled_parent._render(context)
  File "/Users/abhishek.ranjan/virtualenvs/metastore/lib/python2.7/site-packages/django/template/base.py", line 142, in _render
    return self.nodelist.render(context)
  File "/Users/abhishek.ranjan/virtualenvs/metastore/lib/python2.7/site-packages/django/template/base.py", line 844, in render
    bit = self.render_node(node, context)
  File "/Users/abhishek.ranjan/virtualenvs/metastore/lib/python2.7/site-packages/django/template/debug.py", line 80, in render_node
    return node.render(context)
  File "/Users/abhishek.ranjan/virtualenvs/metastore/lib/python2.7/site-packages/django/template/loader_tags.py", line 65, in render
    result = block.nodelist.render(context)
  File "/Users/abhishek.ranjan/virtualenvs/metastore/lib/python2.7/site-packages/django/template/base.py", line 844, in render
    bit = self.render_node(node, context)
  File "/Users/abhishek.ranjan/virtualenvs/metastore/lib/python2.7/site-packages/django/template/debug.py", line 80, in render_node
    return node.render(context)
  File "/Users/abhishek.ranjan/virtualenvs/metastore/lib/python2.7/site-packages/django/template/defaulttags.py", line 458, in render
    six.reraise(*exc_info)
  File "/Users/abhishek.ranjan/virtualenvs/metastore/lib/python2.7/site-packages/django/template/defaulttags.py", line 444, in render
    url = reverse(view_name, args=args, kwargs=kwargs, current_app=context.current_app)
  File "/Users/abhishek.ranjan/virtualenvs/metastore/lib/python2.7/site-packages/django/core/urlresolvers.py", line 551, in reverse
    return iri_to_uri(resolver._reverse_with_prefix(view, prefix, *args, **kwargs))
  File "/Users/abhishek.ranjan/virtualenvs/metastore/lib/python2.7/site-packages/django/core/urlresolvers.py", line 468, in _reverse_with_prefix
    (lookup_view_s, args, kwargs, len(patterns), patterns))
NoReverseMatch: Reverse for 'grp_related_lookup' with arguments '()' and keyword arguments '{}' not found. 0 pattern(s) tried: []
ERROR 2017-02-16 15:25:11,207 base 72505 4520022016 Internal Server Error: /admin/metastore/videos/2/
Traceback (most recent call last):
  File "/Users/abhishek.ranjan/virtualenvs/metastore/lib/python2.7/site-packages/django/core/handlers/base.py", line 137, in get_response
    response = response.render()
  File "/Users/abhishek.ranjan/virtualenvs/metastore/lib/python2.7/site-packages/django/template/response.py", line 103, in render
    self.content = self.rendered_content
  File "/Users/abhishek.ranjan/virtualenvs/metastore/lib/python2.7/site-packages/django/template/response.py", line 80, in rendered_content
    content = template.render(context)
  File "/Users/abhishek.ranjan/virtualenvs/metastore/lib/python2.7/site-packages/django/template/base.py", line 148, in render
    return self._render(context)
  File "/Users/abhishek.ranjan/virtualenvs/metastore/lib/python2.7/site-packages/django/template/base.py", line 142, in _render
    return self.nodelist.render(context)
  File "/Users/abhishek.ranjan/virtualenvs/metastore/lib/python2.7/site-packages/django/template/base.py", line 844, in render
    bit = self.render_node(node, context)
  File "/Users/abhishek.ranjan/virtualenvs/metastore/lib/python2.7/site-packages/django/template/debug.py", line 80, in render_node
    return node.render(context)
  File "/Users/abhishek.ranjan/virtualenvs/metastore/lib/python2.7/site-packages/django/template/loader_tags.py", line 126, in render
    return compiled_parent._render(context)
  File "/Users/abhishek.ranjan/virtualenvs/metastore/lib/python2.7/site-packages/django/template/base.py", line 142, in _render
    return self.nodelist.render(context)
  File "/Users/abhishek.ranjan/virtualenvs/metastore/lib/python2.7/site-packages/django/template/base.py", line 844, in render
    bit = self.render_node(node, context)
  File "/Users/abhishek.ranjan/virtualenvs/metastore/lib/python2.7/site-packages/django/template/debug.py", line 80, in render_node
    return node.render(context)
  File "/Users/abhishek.ranjan/virtualenvs/metastore/lib/python2.7/site-packages/django/template/loader_tags.py", line 126, in render
    return compiled_parent._render(context)
  File "/Users/abhishek.ranjan/virtualenvs/metastore/lib/python2.7/site-packages/django/template/base.py", line 142, in _render
    return self.nodelist.render(context)
  File "/Users/abhishek.ranjan/virtualenvs/metastore/lib/python2.7/site-packages/django/template/base.py", line 844, in render
    bit = self.render_node(node, context)
  File "/Users/abhishek.ranjan/virtualenvs/metastore/lib/python2.7/site-packages/django/template/debug.py", line 80, in render_node
    return node.render(context)
  File "/Users/abhishek.ranjan/virtualenvs/metastore/lib/python2.7/site-packages/django/template/loader_tags.py", line 65, in render
    result = block.nodelist.render(context)
  File "/Users/abhishek.ranjan/virtualenvs/metastore/lib/python2.7/site-packages/django/template/base.py", line 844, in render
    bit = self.render_node(node, context)
  File "/Users/abhishek.ranjan/virtualenvs/metastore/lib/python2.7/site-packages/django/template/debug.py", line 80, in render_node
    return node.render(context)
  File "/Users/abhishek.ranjan/virtualenvs/metastore/lib/python2.7/site-packages/django/template/defaulttags.py", line 458, in render
    six.reraise(*exc_info)
  File "/Users/abhishek.ranjan/virtualenvs/metastore/lib/python2.7/site-packages/django/template/defaulttags.py", line 444, in render
    url = reverse(view_name, args=args, kwargs=kwargs, current_app=context.current_app)
  File "/Users/abhishek.ranjan/virtualenvs/metastore/lib/python2.7/site-packages/django/core/urlresolvers.py", line 551, in reverse
    return iri_to_uri(resolver._reverse_with_prefix(view, prefix, *args, **kwargs))
  File "/Users/abhishek.ranjan/virtualenvs/metastore/lib/python2.7/site-packages/django/core/urlresolvers.py", line 468, in _reverse_with_prefix
    (lookup_view_s, args, kwargs, len(patterns), patterns))
NoReverseMatch: Reverse for 'grp_related_lookup' with arguments '()' and keyword arguments '{}' not found. 0 pattern(s) tried: []
ERROR 2017-02-27 12:42:37,828 base 32440 4560543744 Internal Server Error: /api/meta/v2/videos/
Traceback (most recent call last):
  File "/Users/abhishek.ranjan/virtualenvs/metastore/lib/python2.7/site-packages/django/core/handlers/base.py", line 98, in get_response
    resolver_match = resolver.resolve(request.path_info)
  File "/Users/abhishek.ranjan/virtualenvs/metastore/lib/python2.7/site-packages/django/core/urlresolvers.py", line 343, in resolve
    for pattern in self.url_patterns:
  File "/Users/abhishek.ranjan/virtualenvs/metastore/lib/python2.7/site-packages/django/core/urlresolvers.py", line 372, in url_patterns
    patterns = getattr(self.urlconf_module, "urlpatterns", self.urlconf_module)
  File "/Users/abhishek.ranjan/virtualenvs/metastore/lib/python2.7/site-packages/django/core/urlresolvers.py", line 366, in urlconf_module
    self._urlconf_module = import_module(self.urlconf_name)
  File "/System/Library/Frameworks/Python.framework/Versions/2.7/lib/python2.7/importlib/__init__.py", line 37, in import_module
    __import__(name)
  File "/Users/abhishek.ranjan/lols/metastore/metastore/urls.py", line 6, in <module>
    from metastore.api.resources import resources
  File "/Users/abhishek.ranjan/lols/metastore/metastore/api/resources/resources.py", line 33
    import youtube-dl
                  ^
SyntaxError: invalid syntax
ERROR 2017-02-27 12:42:48,349 base 32440 4560543744 Internal Server Error: /api/meta/v2/videos/
Traceback (most recent call last):
  File "/Users/abhishek.ranjan/virtualenvs/metastore/lib/python2.7/site-packages/django/core/handlers/base.py", line 98, in get_response
    resolver_match = resolver.resolve(request.path_info)
  File "/Users/abhishek.ranjan/virtualenvs/metastore/lib/python2.7/site-packages/django/core/urlresolvers.py", line 343, in resolve
    for pattern in self.url_patterns:
  File "/Users/abhishek.ranjan/virtualenvs/metastore/lib/python2.7/site-packages/django/core/urlresolvers.py", line 372, in url_patterns
    patterns = getattr(self.urlconf_module, "urlpatterns", self.urlconf_module)
  File "/Users/abhishek.ranjan/virtualenvs/metastore/lib/python2.7/site-packages/django/core/urlresolvers.py", line 366, in urlconf_module
    self._urlconf_module = import_module(self.urlconf_name)
  File "/System/Library/Frameworks/Python.framework/Versions/2.7/lib/python2.7/importlib/__init__.py", line 37, in import_module
    __import__(name)
  File "/Users/abhishek.ranjan/lols/metastore/metastore/urls.py", line 6, in <module>
    from metastore.api.resources import resources
  File "/Users/abhishek.ranjan/lols/metastore/metastore/api/resources/resources.py", line 33
    import youtube-dl
                  ^
SyntaxError: invalid syntax
ERROR 2017-02-27 12:43:11,732 base 32440 4560543744 Internal Server Error: /api/meta/v2/videos/
Traceback (most recent call last):
  File "/Users/abhishek.ranjan/virtualenvs/metastore/lib/python2.7/site-packages/django/core/handlers/base.py", line 98, in get_response
    resolver_match = resolver.resolve(request.path_info)
  File "/Users/abhishek.ranjan/virtualenvs/metastore/lib/python2.7/site-packages/django/core/urlresolvers.py", line 343, in resolve
    for pattern in self.url_patterns:
  File "/Users/abhishek.ranjan/virtualenvs/metastore/lib/python2.7/site-packages/django/core/urlresolvers.py", line 372, in url_patterns
    patterns = getattr(self.urlconf_module, "urlpatterns", self.urlconf_module)
  File "/Users/abhishek.ranjan/virtualenvs/metastore/lib/python2.7/site-packages/django/core/urlresolvers.py", line 366, in urlconf_module
    self._urlconf_module = import_module(self.urlconf_name)
  File "/System/Library/Frameworks/Python.framework/Versions/2.7/lib/python2.7/importlib/__init__.py", line 37, in import_module
    __import__(name)
  File "/Users/abhishek.ranjan/lols/metastore/metastore/urls.py", line 6, in <module>
    from metastore.api.resources import resources
  File "/Users/abhishek.ranjan/lols/metastore/metastore/api/resources/resources.py", line 83, in <module>
    class VideosResource(BaseModelResource):
  File "/Users/abhishek.ranjan/virtualenvs/metastore/lib/python2.7/site-packages/tastypie/resources.py", line 1713, in __new__
    new_class = super(ModelDeclarativeMetaclass, cls).__new__(cls, name, bases, attrs)
  File "/Users/abhishek.ranjan/virtualenvs/metastore/lib/python2.7/site-packages/tastypie/resources.py", line 161, in __new__
    field_object.contribute_to_class(new_class, field_name)
TypeError: Error when calling the metaclass bases
    unbound method contribute_to_class() must be called with CharField instance as first argument (got ModelDeclarativeMetaclass instance instead)
ERROR 2017-02-27 12:43:14,385 base 32440 4560543744 Internal Server Error: /api/meta/v2/videos/
Traceback (most recent call last):
  File "/Users/abhishek.ranjan/virtualenvs/metastore/lib/python2.7/site-packages/django/core/handlers/base.py", line 98, in get_response
    resolver_match = resolver.resolve(request.path_info)
  File "/Users/abhishek.ranjan/virtualenvs/metastore/lib/python2.7/site-packages/django/core/urlresolvers.py", line 343, in resolve
    for pattern in self.url_patterns:
  File "/Users/abhishek.ranjan/virtualenvs/metastore/lib/python2.7/site-packages/django/core/urlresolvers.py", line 372, in url_patterns
    patterns = getattr(self.urlconf_module, "urlpatterns", self.urlconf_module)
  File "/Users/abhishek.ranjan/virtualenvs/metastore/lib/python2.7/site-packages/django/core/urlresolvers.py", line 366, in urlconf_module
    self._urlconf_module = import_module(self.urlconf_name)
  File "/System/Library/Frameworks/Python.framework/Versions/2.7/lib/python2.7/importlib/__init__.py", line 37, in import_module
    __import__(name)
  File "/Users/abhishek.ranjan/lols/metastore/metastore/urls.py", line 6, in <module>
    from metastore.api.resources import resources
  File "/Users/abhishek.ranjan/lols/metastore/metastore/api/resources/resources.py", line 83, in <module>
    class VideosResource(BaseModelResource):
  File "/Users/abhishek.ranjan/virtualenvs/metastore/lib/python2.7/site-packages/tastypie/resources.py", line 1713, in __new__
    new_class = super(ModelDeclarativeMetaclass, cls).__new__(cls, name, bases, attrs)
  File "/Users/abhishek.ranjan/virtualenvs/metastore/lib/python2.7/site-packages/tastypie/resources.py", line 161, in __new__
    field_object.contribute_to_class(new_class, field_name)
TypeError: Error when calling the metaclass bases
    unbound method contribute_to_class() must be called with CharField instance as first argument (got ModelDeclarativeMetaclass instance instead)
ERROR 2017-02-27 12:43:52,724 base 32883 4418039808 Internal Server Error: /api/meta/v2/videos/
Traceback (most recent call last):
  File "/Users/abhishek.ranjan/virtualenvs/metastore/lib/python2.7/site-packages/django/core/handlers/base.py", line 98, in get_response
    resolver_match = resolver.resolve(request.path_info)
  File "/Users/abhishek.ranjan/virtualenvs/metastore/lib/python2.7/site-packages/django/core/urlresolvers.py", line 343, in resolve
    for pattern in self.url_patterns:
  File "/Users/abhishek.ranjan/virtualenvs/metastore/lib/python2.7/site-packages/django/core/urlresolvers.py", line 372, in url_patterns
    patterns = getattr(self.urlconf_module, "urlpatterns", self.urlconf_module)
  File "/Users/abhishek.ranjan/virtualenvs/metastore/lib/python2.7/site-packages/django/core/urlresolvers.py", line 366, in urlconf_module
    self._urlconf_module = import_module(self.urlconf_name)
  File "/System/Library/Frameworks/Python.framework/Versions/2.7/lib/python2.7/importlib/__init__.py", line 37, in import_module
    __import__(name)
  File "/Users/abhishek.ranjan/lols/metastore/metastore/urls.py", line 6, in <module>
    from metastore.api.resources import resources
  File "/Users/abhishek.ranjan/lols/metastore/metastore/api/resources/resources.py", line 83, in <module>
    class VideosResource(BaseModelResource):
  File "/Users/abhishek.ranjan/virtualenvs/metastore/lib/python2.7/site-packages/tastypie/resources.py", line 1713, in __new__
    new_class = super(ModelDeclarativeMetaclass, cls).__new__(cls, name, bases, attrs)
  File "/Users/abhishek.ranjan/virtualenvs/metastore/lib/python2.7/site-packages/tastypie/resources.py", line 161, in __new__
    field_object.contribute_to_class(new_class, field_name)
TypeError: Error when calling the metaclass bases
    unbound method contribute_to_class() must be called with CharField instance as first argument (got ModelDeclarativeMetaclass instance instead)
ERROR 2017-02-27 12:44:28,924 base 32883 4418039808 Internal Server Error: /api/meta/v2/videos/
Traceback (most recent call last):
  File "/Users/abhishek.ranjan/virtualenvs/metastore/lib/python2.7/site-packages/django/core/handlers/base.py", line 98, in get_response
    resolver_match = resolver.resolve(request.path_info)
  File "/Users/abhishek.ranjan/virtualenvs/metastore/lib/python2.7/site-packages/django/core/urlresolvers.py", line 343, in resolve
    for pattern in self.url_patterns:
  File "/Users/abhishek.ranjan/virtualenvs/metastore/lib/python2.7/site-packages/django/core/urlresolvers.py", line 372, in url_patterns
    patterns = getattr(self.urlconf_module, "urlpatterns", self.urlconf_module)
  File "/Users/abhishek.ranjan/virtualenvs/metastore/lib/python2.7/site-packages/django/core/urlresolvers.py", line 366, in urlconf_module
    self._urlconf_module = import_module(self.urlconf_name)
  File "/System/Library/Frameworks/Python.framework/Versions/2.7/lib/python2.7/importlib/__init__.py", line 37, in import_module
    __import__(name)
  File "/Users/abhishek.ranjan/lols/metastore/metastore/urls.py", line 6, in <module>
    from metastore.api.resources import resources
  File "/Users/abhishek.ranjan/lols/metastore/metastore/api/resources/resources.py", line 83, in <module>
    class VideosResource(BaseModelResource):
  File "/Users/abhishek.ranjan/virtualenvs/metastore/lib/python2.7/site-packages/tastypie/resources.py", line 1713, in __new__
    new_class = super(ModelDeclarativeMetaclass, cls).__new__(cls, name, bases, attrs)
  File "/Users/abhishek.ranjan/virtualenvs/metastore/lib/python2.7/site-packages/tastypie/resources.py", line 161, in __new__
    field_object.contribute_to_class(new_class, field_name)
TypeError: Error when calling the metaclass bases
    unbound method contribute_to_class() must be called with CharField instance as first argument (got ModelDeclarativeMetaclass instance instead)
ERROR 2017-02-27 12:44:53,031 base 32883 4418039808 Internal Server Error: /api/meta/v2/videos/
Traceback (most recent call last):
  File "/Users/abhishek.ranjan/virtualenvs/metastore/lib/python2.7/site-packages/django/core/handlers/base.py", line 98, in get_response
    resolver_match = resolver.resolve(request.path_info)
  File "/Users/abhishek.ranjan/virtualenvs/metastore/lib/python2.7/site-packages/django/core/urlresolvers.py", line 343, in resolve
    for pattern in self.url_patterns:
  File "/Users/abhishek.ranjan/virtualenvs/metastore/lib/python2.7/site-packages/django/core/urlresolvers.py", line 372, in url_patterns
    patterns = getattr(self.urlconf_module, "urlpatterns", self.urlconf_module)
  File "/Users/abhishek.ranjan/virtualenvs/metastore/lib/python2.7/site-packages/django/core/urlresolvers.py", line 366, in urlconf_module
    self._urlconf_module = import_module(self.urlconf_name)
  File "/System/Library/Frameworks/Python.framework/Versions/2.7/lib/python2.7/importlib/__init__.py", line 37, in import_module
    __import__(name)
  File "/Users/abhishek.ranjan/lols/metastore/metastore/urls.py", line 6, in <module>
    from metastore.api.resources import resources
  File "/Users/abhishek.ranjan/lols/metastore/metastore/api/resources/resources.py", line 83, in <module>
    class VideosResource(BaseModelResource):
  File "/Users/abhishek.ranjan/virtualenvs/metastore/lib/python2.7/site-packages/tastypie/resources.py", line 1713, in __new__
    new_class = super(ModelDeclarativeMetaclass, cls).__new__(cls, name, bases, attrs)
  File "/Users/abhishek.ranjan/virtualenvs/metastore/lib/python2.7/site-packages/tastypie/resources.py", line 161, in __new__
    field_object.contribute_to_class(new_class, field_name)
TypeError: Error when calling the metaclass bases
    unbound method contribute_to_class() must be called with CharField instance as first argument (got ModelDeclarativeMetaclass instance instead)
ERROR 2017-02-27 12:44:55,113 base 32883 4422246400 Internal Server Error: /api/meta/v2/videos/
Traceback (most recent call last):
  File "/Users/abhishek.ranjan/virtualenvs/metastore/lib/python2.7/site-packages/django/core/handlers/base.py", line 98, in get_response
    resolver_match = resolver.resolve(request.path_info)
  File "/Users/abhishek.ranjan/virtualenvs/metastore/lib/python2.7/site-packages/django/core/urlresolvers.py", line 343, in resolve
    for pattern in self.url_patterns:
  File "/Users/abhishek.ranjan/virtualenvs/metastore/lib/python2.7/site-packages/django/core/urlresolvers.py", line 372, in url_patterns
    patterns = getattr(self.urlconf_module, "urlpatterns", self.urlconf_module)
  File "/Users/abhishek.ranjan/virtualenvs/metastore/lib/python2.7/site-packages/django/core/urlresolvers.py", line 366, in urlconf_module
    self._urlconf_module = import_module(self.urlconf_name)
  File "/System/Library/Frameworks/Python.framework/Versions/2.7/lib/python2.7/importlib/__init__.py", line 37, in import_module
    __import__(name)
  File "/Users/abhishek.ranjan/lols/metastore/metastore/urls.py", line 6, in <module>
    from metastore.api.resources import resources
  File "/Users/abhishek.ranjan/lols/metastore/metastore/api/resources/resources.py", line 83, in <module>
    class VideosResource(BaseModelResource):
  File "/Users/abhishek.ranjan/virtualenvs/metastore/lib/python2.7/site-packages/tastypie/resources.py", line 1713, in __new__
    new_class = super(ModelDeclarativeMetaclass, cls).__new__(cls, name, bases, attrs)
  File "/Users/abhishek.ranjan/virtualenvs/metastore/lib/python2.7/site-packages/tastypie/resources.py", line 161, in __new__
    field_object.contribute_to_class(new_class, field_name)
TypeError: Error when calling the metaclass bases
    unbound method contribute_to_class() must be called with CharField instance as first argument (got ModelDeclarativeMetaclass instance instead)
ERROR 2017-02-27 12:44:58,734 base 32883 4418039808 Internal Server Error: /api/meta/v2/videos/
Traceback (most recent call last):
  File "/Users/abhishek.ranjan/virtualenvs/metastore/lib/python2.7/site-packages/django/core/handlers/base.py", line 98, in get_response
    resolver_match = resolver.resolve(request.path_info)
  File "/Users/abhishek.ranjan/virtualenvs/metastore/lib/python2.7/site-packages/django/core/urlresolvers.py", line 343, in resolve
    for pattern in self.url_patterns:
  File "/Users/abhishek.ranjan/virtualenvs/metastore/lib/python2.7/site-packages/django/core/urlresolvers.py", line 372, in url_patterns
    patterns = getattr(self.urlconf_module, "urlpatterns", self.urlconf_module)
  File "/Users/abhishek.ranjan/virtualenvs/metastore/lib/python2.7/site-packages/django/core/urlresolvers.py", line 366, in urlconf_module
    self._urlconf_module = import_module(self.urlconf_name)
  File "/System/Library/Frameworks/Python.framework/Versions/2.7/lib/python2.7/importlib/__init__.py", line 37, in import_module
    __import__(name)
  File "/Users/abhishek.ranjan/lols/metastore/metastore/urls.py", line 6, in <module>
    from metastore.api.resources import resources
  File "/Users/abhishek.ranjan/lols/metastore/metastore/api/resources/resources.py", line 83, in <module>
    class VideosResource(BaseModelResource):
  File "/Users/abhishek.ranjan/virtualenvs/metastore/lib/python2.7/site-packages/tastypie/resources.py", line 1713, in __new__
    new_class = super(ModelDeclarativeMetaclass, cls).__new__(cls, name, bases, attrs)
  File "/Users/abhishek.ranjan/virtualenvs/metastore/lib/python2.7/site-packages/tastypie/resources.py", line 161, in __new__
    field_object.contribute_to_class(new_class, field_name)
TypeError: Error when calling the metaclass bases
    unbound method contribute_to_class() must be called with CharField instance as first argument (got ModelDeclarativeMetaclass instance instead)
ERROR 2017-02-27 12:45:00,216 base 32883 4422246400 Internal Server Error: /api/meta/v2/videos/
Traceback (most recent call last):
  File "/Users/abhishek.ranjan/virtualenvs/metastore/lib/python2.7/site-packages/django/core/handlers/base.py", line 98, in get_response
    resolver_match = resolver.resolve(request.path_info)
  File "/Users/abhishek.ranjan/virtualenvs/metastore/lib/python2.7/site-packages/django/core/urlresolvers.py", line 343, in resolve
    for pattern in self.url_patterns:
  File "/Users/abhishek.ranjan/virtualenvs/metastore/lib/python2.7/site-packages/django/core/urlresolvers.py", line 372, in url_patterns
    patterns = getattr(self.urlconf_module, "urlpatterns", self.urlconf_module)
  File "/Users/abhishek.ranjan/virtualenvs/metastore/lib/python2.7/site-packages/django/core/urlresolvers.py", line 366, in urlconf_module
    self._urlconf_module = import_module(self.urlconf_name)
  File "/System/Library/Frameworks/Python.framework/Versions/2.7/lib/python2.7/importlib/__init__.py", line 37, in import_module
    __import__(name)
  File "/Users/abhishek.ranjan/lols/metastore/metastore/urls.py", line 6, in <module>
    from metastore.api.resources import resources
  File "/Users/abhishek.ranjan/lols/metastore/metastore/api/resources/resources.py", line 83, in <module>
    class VideosResource(BaseModelResource):
  File "/Users/abhishek.ranjan/virtualenvs/metastore/lib/python2.7/site-packages/tastypie/resources.py", line 1713, in __new__
    new_class = super(ModelDeclarativeMetaclass, cls).__new__(cls, name, bases, attrs)
  File "/Users/abhishek.ranjan/virtualenvs/metastore/lib/python2.7/site-packages/tastypie/resources.py", line 161, in __new__
    field_object.contribute_to_class(new_class, field_name)
TypeError: Error when calling the metaclass bases
    unbound method contribute_to_class() must be called with CharField instance as first argument (got ModelDeclarativeMetaclass instance instead)
ERROR 2017-03-01 10:46:59,220 base 81293 4575137792 Internal Server Error: /admin/metastore/videos/1/
Traceback (most recent call last):
  File "/Users/abhishek.ranjan/virtualenvs/metastore/lib/python2.7/site-packages/django/core/handlers/base.py", line 137, in get_response
    response = response.render()
  File "/Users/abhishek.ranjan/virtualenvs/metastore/lib/python2.7/site-packages/django/template/response.py", line 103, in render
    self.content = self.rendered_content
  File "/Users/abhishek.ranjan/virtualenvs/metastore/lib/python2.7/site-packages/django/template/response.py", line 80, in rendered_content
    content = template.render(context)
  File "/Users/abhishek.ranjan/virtualenvs/metastore/lib/python2.7/site-packages/django/template/base.py", line 148, in render
    return self._render(context)
  File "/Users/abhishek.ranjan/virtualenvs/metastore/lib/python2.7/site-packages/django/template/base.py", line 142, in _render
    return self.nodelist.render(context)
  File "/Users/abhishek.ranjan/virtualenvs/metastore/lib/python2.7/site-packages/django/template/base.py", line 844, in render
    bit = self.render_node(node, context)
  File "/Users/abhishek.ranjan/virtualenvs/metastore/lib/python2.7/site-packages/django/template/debug.py", line 80, in render_node
    return node.render(context)
  File "/Users/abhishek.ranjan/virtualenvs/metastore/lib/python2.7/site-packages/django/template/loader_tags.py", line 126, in render
    return compiled_parent._render(context)
  File "/Users/abhishek.ranjan/virtualenvs/metastore/lib/python2.7/site-packages/django/template/base.py", line 142, in _render
    return self.nodelist.render(context)
  File "/Users/abhishek.ranjan/virtualenvs/metastore/lib/python2.7/site-packages/django/template/base.py", line 844, in render
    bit = self.render_node(node, context)
  File "/Users/abhishek.ranjan/virtualenvs/metastore/lib/python2.7/site-packages/django/template/debug.py", line 80, in render_node
    return node.render(context)
  File "/Users/abhishek.ranjan/virtualenvs/metastore/lib/python2.7/site-packages/django/template/loader_tags.py", line 126, in render
    return compiled_parent._render(context)
  File "/Users/abhishek.ranjan/virtualenvs/metastore/lib/python2.7/site-packages/django/template/base.py", line 142, in _render
    return self.nodelist.render(context)
  File "/Users/abhishek.ranjan/virtualenvs/metastore/lib/python2.7/site-packages/django/template/base.py", line 844, in render
    bit = self.render_node(node, context)
  File "/Users/abhishek.ranjan/virtualenvs/metastore/lib/python2.7/site-packages/django/template/debug.py", line 80, in render_node
    return node.render(context)
  File "/Users/abhishek.ranjan/virtualenvs/metastore/lib/python2.7/site-packages/django/template/loader_tags.py", line 65, in render
    result = block.nodelist.render(context)
  File "/Users/abhishek.ranjan/virtualenvs/metastore/lib/python2.7/site-packages/django/template/base.py", line 844, in render
    bit = self.render_node(node, context)
  File "/Users/abhishek.ranjan/virtualenvs/metastore/lib/python2.7/site-packages/django/template/debug.py", line 80, in render_node
    return node.render(context)
  File "/Users/abhishek.ranjan/virtualenvs/metastore/lib/python2.7/site-packages/django/template/loader_tags.py", line 65, in render
    result = block.nodelist.render(context)
  File "/Users/abhishek.ranjan/virtualenvs/metastore/lib/python2.7/site-packages/django/template/base.py", line 844, in render
    bit = self.render_node(node, context)
  File "/Users/abhishek.ranjan/virtualenvs/metastore/lib/python2.7/site-packages/django/template/debug.py", line 80, in render_node
    return node.render(context)
  File "/Users/abhishek.ranjan/virtualenvs/metastore/lib/python2.7/site-packages/django/template/defaulttags.py", line 201, in render
    nodelist.append(node.render(context))
  File "/Users/abhishek.ranjan/virtualenvs/metastore/lib/python2.7/site-packages/django/template/loader_tags.py", line 150, in render
    return template.render(context)
  File "/Users/abhishek.ranjan/virtualenvs/metastore/lib/python2.7/site-packages/django/template/base.py", line 148, in render
    return self._render(context)
  File "/Users/abhishek.ranjan/virtualenvs/metastore/lib/python2.7/site-packages/django/template/base.py", line 142, in _render
    return self.nodelist.render(context)
  File "/Users/abhishek.ranjan/virtualenvs/metastore/lib/python2.7/site-packages/django/template/base.py", line 844, in render
    bit = self.render_node(node, context)
  File "/Users/abhishek.ranjan/virtualenvs/metastore/lib/python2.7/site-packages/django/template/debug.py", line 80, in render_node
    return node.render(context)
  File "/Users/abhishek.ranjan/virtualenvs/metastore/lib/python2.7/site-packages/django/template/defaulttags.py", line 402, in render
    return strip_spaces_between_tags(self.nodelist.render(context).strip())
  File "/Users/abhishek.ranjan/virtualenvs/metastore/lib/python2.7/site-packages/django/template/base.py", line 844, in render
    bit = self.render_node(node, context)
  File "/Users/abhishek.ranjan/virtualenvs/metastore/lib/python2.7/site-packages/django/template/debug.py", line 80, in render_node
    return node.render(context)
  File "/Users/abhishek.ranjan/virtualenvs/metastore/lib/python2.7/site-packages/django/template/defaulttags.py", line 201, in render
    nodelist.append(node.render(context))
  File "/Users/abhishek.ranjan/virtualenvs/metastore/lib/python2.7/site-packages/django/template/defaulttags.py", line 312, in render
    return nodelist.render(context)
  File "/Users/abhishek.ranjan/virtualenvs/metastore/lib/python2.7/site-packages/django/template/base.py", line 844, in render
    bit = self.render_node(node, context)
  File "/Users/abhishek.ranjan/virtualenvs/metastore/lib/python2.7/site-packages/django/template/debug.py", line 80, in render_node
    return node.render(context)
  File "/Users/abhishek.ranjan/virtualenvs/metastore/lib/python2.7/site-packages/django/template/defaulttags.py", line 305, in render
    match = condition.eval(context)
  File "/Users/abhishek.ranjan/virtualenvs/metastore/lib/python2.7/site-packages/django/template/defaulttags.py", line 898, in eval
    return self.value.resolve(context, ignore_failures=True)
  File "/Users/abhishek.ranjan/virtualenvs/metastore/lib/python2.7/site-packages/django/template/base.py", line 596, in resolve
    obj = self.var.resolve(context)
  File "/Users/abhishek.ranjan/virtualenvs/metastore/lib/python2.7/site-packages/django/template/base.py", line 734, in resolve
    value = self._resolve_lookup(context)
  File "/Users/abhishek.ranjan/virtualenvs/metastore/lib/python2.7/site-packages/django/template/base.py", line 788, in _resolve_lookup
    current = current()
  File "/Users/abhishek.ranjan/virtualenvs/metastore/lib/python2.7/site-packages/django/contrib/admin/helpers.py", line 108, in errors
    return mark_safe('\n'.join(self.form[f].errors.as_ul() for f in self.fields if f not in self.readonly_fields).strip('\n'))
  File "/Users/abhishek.ranjan/virtualenvs/metastore/lib/python2.7/site-packages/django/contrib/admin/helpers.py", line 108, in <genexpr>
    return mark_safe('\n'.join(self.form[f].errors.as_ul() for f in self.fields if f not in self.readonly_fields).strip('\n'))
  File "/Users/abhishek.ranjan/virtualenvs/metastore/lib/python2.7/site-packages/django/forms/forms.py", line 147, in __getitem__
    "Key %r not found in '%s'" % (name, self.__class__.__name__))
KeyError: u"Key 'id' not found in 'VideosForm'"
ERROR 2017-03-04 10:21:05,331 base 55822 4435423232 Internal Server Error: /api/meta/v2/download/
Traceback (most recent call last):
  File "/Users/abhishek.ranjan/virtualenvs/metastore/lib/python2.7/site-packages/django/core/handlers/base.py", line 98, in get_response
    resolver_match = resolver.resolve(request.path_info)
  File "/Users/abhishek.ranjan/virtualenvs/metastore/lib/python2.7/site-packages/django/core/urlresolvers.py", line 343, in resolve
    for pattern in self.url_patterns:
  File "/Users/abhishek.ranjan/virtualenvs/metastore/lib/python2.7/site-packages/django/core/urlresolvers.py", line 372, in url_patterns
    patterns = getattr(self.urlconf_module, "urlpatterns", self.urlconf_module)
  File "/Users/abhishek.ranjan/virtualenvs/metastore/lib/python2.7/site-packages/django/core/urlresolvers.py", line 366, in urlconf_module
    self._urlconf_module = import_module(self.urlconf_name)
  File "/System/Library/Frameworks/Python.framework/Versions/2.7/lib/python2.7/importlib/__init__.py", line 37, in import_module
    __import__(name)
  File "/Users/abhishek.ranjan/lols/metastore/metastore/urls.py", line 6, in <module>
    from metastore.api.resources import resources
  File "/Users/abhishek.ranjan/lols/metastore/metastore/api/resources/resources.py", line 34, in <module>
    from tastypie import Resource
ImportError: cannot import name Resource
ERROR 2017-03-04 10:21:39,855 base 55822 4435423232 Internal Server Error: /api/meta/v2/download/
Traceback (most recent call last):
  File "/Users/abhishek.ranjan/virtualenvs/metastore/lib/python2.7/site-packages/django/core/handlers/base.py", line 98, in get_response
    resolver_match = resolver.resolve(request.path_info)
  File "/Users/abhishek.ranjan/virtualenvs/metastore/lib/python2.7/site-packages/django/core/urlresolvers.py", line 343, in resolve
    for pattern in self.url_patterns:
  File "/Users/abhishek.ranjan/virtualenvs/metastore/lib/python2.7/site-packages/django/core/urlresolvers.py", line 372, in url_patterns
    patterns = getattr(self.urlconf_module, "urlpatterns", self.urlconf_module)
  File "/Users/abhishek.ranjan/virtualenvs/metastore/lib/python2.7/site-packages/django/core/urlresolvers.py", line 366, in urlconf_module
    self._urlconf_module = import_module(self.urlconf_name)
  File "/System/Library/Frameworks/Python.framework/Versions/2.7/lib/python2.7/importlib/__init__.py", line 37, in import_module
    __import__(name)
  File "/Users/abhishek.ranjan/lols/metastore/metastore/urls.py", line 22, in <module>
    v2_api.register(resources.DownloadResource())
  File "/Users/abhishek.ranjan/virtualenvs/metastore/lib/python2.7/site-packages/tastypie/api.py", line 54, in register
    resource.__class__.Meta.api_name = self.api_name
AttributeError: type object 'DownloadResource' has no attribute 'Meta'
ERROR 2017-03-04 10:21:41,353 base 55822 4439629824 Internal Server Error: /api/meta/v2/download/
Traceback (most recent call last):
  File "/Users/abhishek.ranjan/virtualenvs/metastore/lib/python2.7/site-packages/django/core/handlers/base.py", line 98, in get_response
    resolver_match = resolver.resolve(request.path_info)
  File "/Users/abhishek.ranjan/virtualenvs/metastore/lib/python2.7/site-packages/django/core/urlresolvers.py", line 343, in resolve
    for pattern in self.url_patterns:
  File "/Users/abhishek.ranjan/virtualenvs/metastore/lib/python2.7/site-packages/django/core/urlresolvers.py", line 372, in url_patterns
    patterns = getattr(self.urlconf_module, "urlpatterns", self.urlconf_module)
  File "/Users/abhishek.ranjan/virtualenvs/metastore/lib/python2.7/site-packages/django/core/urlresolvers.py", line 366, in urlconf_module
    self._urlconf_module = import_module(self.urlconf_name)
  File "/System/Library/Frameworks/Python.framework/Versions/2.7/lib/python2.7/importlib/__init__.py", line 37, in import_module
    __import__(name)
  File "/Users/abhishek.ranjan/lols/metastore/metastore/urls.py", line 22, in <module>
    v2_api.register(resources.DownloadResource())
  File "/Users/abhishek.ranjan/virtualenvs/metastore/lib/python2.7/site-packages/tastypie/api.py", line 54, in register
    resource.__class__.Meta.api_name = self.api_name
AttributeError: type object 'DownloadResource' has no attribute 'Meta'
ERROR 2017-03-04 10:22:16,006 base 55869 4432281600 Internal Server Error: /api/meta/v2/download/
Traceback (most recent call last):
  File "/Users/abhishek.ranjan/virtualenvs/metastore/lib/python2.7/site-packages/django/core/handlers/base.py", line 98, in get_response
    resolver_match = resolver.resolve(request.path_info)
  File "/Users/abhishek.ranjan/virtualenvs/metastore/lib/python2.7/site-packages/django/core/urlresolvers.py", line 343, in resolve
    for pattern in self.url_patterns:
  File "/Users/abhishek.ranjan/virtualenvs/metastore/lib/python2.7/site-packages/django/core/urlresolvers.py", line 372, in url_patterns
    patterns = getattr(self.urlconf_module, "urlpatterns", self.urlconf_module)
  File "/Users/abhishek.ranjan/virtualenvs/metastore/lib/python2.7/site-packages/django/core/urlresolvers.py", line 366, in urlconf_module
    self._urlconf_module = import_module(self.urlconf_name)
  File "/System/Library/Frameworks/Python.framework/Versions/2.7/lib/python2.7/importlib/__init__.py", line 37, in import_module
    __import__(name)
  File "/Users/abhishek.ranjan/lols/metastore/metastore/urls.py", line 6, in <module>
    from metastore.api.resources import resources
  File "/Users/abhishek.ranjan/lols/metastore/metastore/api/resources/resources.py", line 97, in <module>
    class DownloadResource(Resource):
  File "/Users/abhishek.ranjan/lols/metastore/metastore/api/resources/resources.py", line 98, in DownloadResource
    class Meta(Resource.Meta):
AttributeError: type object 'Resource' has no attribute 'Meta'
ERROR 2017-03-04 10:22:17,288 base 55869 4436488192 Internal Server Error: /api/meta/v2/download/
Traceback (most recent call last):
  File "/Users/abhishek.ranjan/virtualenvs/metastore/lib/python2.7/site-packages/django/core/handlers/base.py", line 98, in get_response
    resolver_match = resolver.resolve(request.path_info)
  File "/Users/abhishek.ranjan/virtualenvs/metastore/lib/python2.7/site-packages/django/core/urlresolvers.py", line 343, in resolve
    for pattern in self.url_patterns:
  File "/Users/abhishek.ranjan/virtualenvs/metastore/lib/python2.7/site-packages/django/core/urlresolvers.py", line 372, in url_patterns
    patterns = getattr(self.urlconf_module, "urlpatterns", self.urlconf_module)
  File "/Users/abhishek.ranjan/virtualenvs/metastore/lib/python2.7/site-packages/django/core/urlresolvers.py", line 366, in urlconf_module
    self._urlconf_module = import_module(self.urlconf_name)
  File "/System/Library/Frameworks/Python.framework/Versions/2.7/lib/python2.7/importlib/__init__.py", line 37, in import_module
    __import__(name)
  File "/Users/abhishek.ranjan/lols/metastore/metastore/urls.py", line 6, in <module>
    from metastore.api.resources import resources
  File "/Users/abhishek.ranjan/lols/metastore/metastore/api/resources/resources.py", line 97, in <module>
    class DownloadResource(Resource):
  File "/Users/abhishek.ranjan/lols/metastore/metastore/api/resources/resources.py", line 98, in DownloadResource
    class Meta(Resource.Meta):
AttributeError: type object 'Resource' has no attribute 'Meta'
ERROR 2017-03-04 10:22:18,725 base 55869 4432281600 Internal Server Error: /api/meta/v2/download/
Traceback (most recent call last):
  File "/Users/abhishek.ranjan/virtualenvs/metastore/lib/python2.7/site-packages/django/core/handlers/base.py", line 98, in get_response
    resolver_match = resolver.resolve(request.path_info)
  File "/Users/abhishek.ranjan/virtualenvs/metastore/lib/python2.7/site-packages/django/core/urlresolvers.py", line 343, in resolve
    for pattern in self.url_patterns:
  File "/Users/abhishek.ranjan/virtualenvs/metastore/lib/python2.7/site-packages/django/core/urlresolvers.py", line 372, in url_patterns
    patterns = getattr(self.urlconf_module, "urlpatterns", self.urlconf_module)
  File "/Users/abhishek.ranjan/virtualenvs/metastore/lib/python2.7/site-packages/django/core/urlresolvers.py", line 366, in urlconf_module
    self._urlconf_module = import_module(self.urlconf_name)
  File "/System/Library/Frameworks/Python.framework/Versions/2.7/lib/python2.7/importlib/__init__.py", line 37, in import_module
    __import__(name)
  File "/Users/abhishek.ranjan/lols/metastore/metastore/urls.py", line 6, in <module>
    from metastore.api.resources import resources
  File "/Users/abhishek.ranjan/lols/metastore/metastore/api/resources/resources.py", line 97, in <module>
    class DownloadResource(Resource):
  File "/Users/abhishek.ranjan/lols/metastore/metastore/api/resources/resources.py", line 98, in DownloadResource
    class Meta(Resource.Meta):
AttributeError: type object 'Resource' has no attribute 'Meta'
